Workbook

Sheet 表紙
B3: 画面設計書
B5: システムID | H5: BPS | M5: システム名 | T5: バトルポータルシュミレーター
B6: サブシステムID | H6: PK | M6: サブシステム名 | T6: ポータル
B7: 画面ID | H7: BPSFRPK05 | M7: 画面名 | T7: 新規会員登録完了
B10: 作成者 | N10: =改訂履歴!AS9 -> 須賀
B11: 作成日 | N11: =改訂履歴!E9 -> 44486
B12: 更新者 | N12: =VLOOKUP(表紙!N14,改訂履歴!B:AS,44,FALSE) -> 須賀
B13: 更新日 | N13: =VLOOKUP(表紙!N14,改訂履歴!B:E,4,FALSE) -> 44486
B14: 版数 | N14: =MAX(改訂履歴!B:B) -> 1

Sheet 改訂履歴
B2: システムID | H2: =表紙!H5 -> BPS | M2: システム名 | T2: =表紙!T5 -> バトルポータルシュミレーター | AS2: 版数 | AV2: =表紙!N14 -> 1
B3: サブシステムID | H3: =表紙!H6 -> PK | M3: サブシステム名 | T3: =表紙!T6 -> ポータル | AJ3: 作成者 | AM3: =表紙!N10 -> 須賀 | AS3: 更新者 | AV3: =表紙!N12 -> 須賀
B4: 画面ID | H4: =表紙!H7 -> BPSFRPK05 | M4: 画面名 | T4: =表紙!T7 -> 新規会員登録完了 | AJ4: 作成日 | AM4: =表紙!N11 -> 44486 | AS4: 更新者 | AV4: =表紙!N13 -> 44486
B6: 改訂履歴
B8: 版数 | E8: 改定日 | I8: 改定シート | P8: 改定内容 | AS8: 担当
B9: 1 | E9: 44486 | I9: 全般 | P9: 新規作成 | AS9: 須賀

Sheet 画面設計
B2: システムID | H2: =表紙!H5 -> BPS | M2: システム名 | T2: =表紙!T5 -> バトルポータルシュミレーター | AS2: 版数 | AV2: =表紙!N14 -> 1
B3: サブシステムID | H3: =表紙!H6 -> PK | M3: サブシステム名 | T3: =表紙!T6 -> ポータル | AJ3: 作成者 | AM3: =表紙!N10 -> 須賀 | AS3: 更新者 | AV3: =表紙!N12 -> 須賀
B4: 画面ID | H4: =表紙!H7 -> BPSFRPK05 | M4: 画面名 | T4: =表紙!T7 -> 新規会員登録完了 | AJ4: 作成日 | AM4: =表紙!N11 -> 44486 | AS4: 更新者 | AV4: =表紙!N13 -> 44486
B6: 画面説明
B7: ◆画面概要
C8: ユーザーの会員登録が完了したことを表示する画面。
B11: ◆遷移元画面
C12: 「BPSFRPK04_新規会員登確認」の上記の内容で登録するボタン押下時に遷移する。
B14: ◆遷移先画面
C15: 「ログインする」ボタン押下時、「BPSFRPK02_ログイン」へ遷移する。
B17: ◆画面遷移フロー
C18: ※画面遷移図を参照

Sheet 画面レイアウト
B2: システムID | H2: =表紙!H5 -> BPS | M2: システム名 | T2: =表紙!T5 -> バトルポータルシュミレーター | AS2: 版数 | AV2: =表紙!N14 -> 1
B3: サブシステムID | H3: =表紙!H6 -> PK | M3: サブシステム名 | T3: =表紙!T6 -> ポータル | AJ3: 作成者 | AM3: =表紙!N10 -> 須賀 | AS3: 更新者 | AV3: =表紙!N12 -> 須賀
B4: 画面ID | H4: =表紙!H7 -> BPSFRPK05 | M4: 画面名 | T4: =表紙!T7 -> 新規会員登録完了 | AJ4: 作成日 | AM4: =表紙!N11 -> 44486 | AS4: 更新者 | AV4: =表紙!N13 -> 44486
B6: 表示条件
B7: １．初期表示_未ログイン
B9: 画面レイアウト（PC）

Sheet 画面項目一覧
B2: システムID | H2: =表紙!H5 -> BPS | M2: システム名 | T2: =表紙!T5 -> バトルポータルシュミレーター | AS2: 版数 | AV2: =表紙!N14 -> 1
B3: サブシステムID | H3: =表紙!H6 -> PK | M3: サブシステム名 | T3: =表紙!T6 -> ポータル | AJ3: 作成者 | AM3: =表紙!N10 -> 須賀 | AS3: 更新者 | AV3: =表紙!N12 -> 須賀
B4: 画面ID | H4: =表紙!H7 -> BPSFRPK05 | M4: 画面名 | T4: =表紙!T7 -> 新規会員登録完了 | AJ4: 作成日 | AM4: =表紙!N11 -> 44486 | AS4: 更新者 | AV4: =表紙!N13 -> 44486
B6: 画面項目一覧
B7: ※1・・・パワー最大値<パワー最小値の時、ダイアログにてエラーを表示する。
B10: 識別ID | E10: 表示用ラベル | L10: タイプ | Q10: 入力 | S10: 出力 | U10: チェック項目 | AE10: 出力元 | AS10: 備考
U11: 桁数 | W11: データ型 （文字列/数字） | Y11: 文字種 （全角/半角） | AA11: 必須 | AC11: 相関 | AE11: 処理名 | AL11: 項目
B12: 1 | E12: ログイン画面 | L12: - | Q12: - | S12: - | U12: - | W12: - | Y12: - | AA12: - | AC12: - | AE12: - | AL12: - | AS12: -
B13: 1-1 | E13: 画面名 | L13: ラベル | Q13: - | S13: - | U13: - | W13: - | Y13: - | AA13: - | AC13: - | AE13: - | AK13: - | AL13: - | AS13: -
B14: 1-2 | E14: ユーザー名またはメールアドレス | L14: ラベル | Q14: - | S14: - | U14: - | W14: - | Y14: - | AA14: - | AC14: - | AE14: - | AK14: - | AL14: - | AS14: -
B15: 1-3 | E15: ユーザー名またはメールアドレス | L15: テキストボックス | Q15: - | S15: - | U15: - | W15: - | Y15: - | AA15: ○ | AC15: - | AE15: - | AK15: - | AL15: - | AS15: -
B16: 1-4 | E16: パスワード | L16: ラベル | Q16: - | S16: - | U16: - | W16: - | Y16: - | AA16: - | AC16: - | AE16: - | AK16: - | AL16: - | AS16: -
B17: 1-5 | E17: パスワード | L17: パスワードボックス | Q17: - | S17: - | U17: - | W17: - | Y17: - | AA17: ○ | AC17: - | AE17: - | AK17: - | AL17: - | AS17: -
B18: 1-6 | E18: 表示 | L18: ボタン | Q18: - | S18: - | U18: - | W18: - | Y18: - | AA18: - | AC18: - | AE18: - | AK18: - | AL18: - | AS18: -
B19: 1-7 | E19: 次回から自動的にログインする | L19: チェックボックス | Q19: - | S19: - | U19: - | W19: - | Y19: - | AA19: - | AC19: - | AE19: - | AK19: - | AL19: - | AS19: 初期値はチェックあり
B20: 1-8 | E20: 新規会員登録はこちら | L20: ボタン | Q20: - | S20: - | U20: - | W20: - | Y20: - | AA20: - | AC20: - | AE20: - | AK20: - | AL20: - | AS20: -
B21: 1-9 | E21: ログイン | L21: ボタン | Q21: - | S21: - | U21: - | W21: - | Y21: - | AA21: - | AC21: - | AE21: - | AK21: - | AL21: - | AS21: 初期値は非活性

Sheet 画面表示制御
B2: システムID | H2: =表紙!H5 -> BPS | M2: システム名 | T2: =表紙!T5 -> バトルポータルシュミレーター | AS2: 版数 | AV2: =表紙!N14 -> 1
B3: サブシステムID | H3: =表紙!H6 -> PK | M3: サブシステム名 | T3: =表紙!T6 -> ポータル | AJ3: 作成者 | AM3: =表紙!N10 -> 須賀 | AS3: 更新者 | AV3: =表紙!N12 -> 須賀
B4: 画面ID | H4: =表紙!H7 -> BPSFRPK05 | M4: 画面名 | T4: =表紙!T7 -> 新規会員登録完了 | AJ4: 作成日 | AM4: =表紙!N11 -> 44486 | AS4: 更新者 | AV4: =表紙!N13 -> 44486
B6: 画面表示制御
B7: ○表示/△非活性/-非表示
B8: ボタン押下時処理はボタン押下の度に表示制御を切り替える。
B9: 以下、セッションによる制御と処理による表示制御を同時に満たす場合のみ項目を表示する。
B12: 識別ID | E12: 表示用ラベル | L12: セッション | T12: 表示処理
L13: ログインフラグ | T13: 初期表示 | X13: ボタン押下時処理
L14: 1.ログイン | P14: 2.ゲスト
B15: 1 | E15: ログイン画面 | L15: ○ | P15: ○ | T15: ○
B16: 1-1 | E16: 画面名 | L16: - | P16: ○ | T16: ○
B17: 1-2 | E17: ユーザー名またはメールアドレス | L17: - | P17: ○ | T17: ○
B18: 1-3 | E18: ユーザー名またはメールアドレス | L18: - | P18: ○ | T18: ○
B19: 1-4 | E19: パスワード | L19: - | P19: ○ | T19: ○
B20: 1-5 | E20: パスワード | L20: - | P20: ○ | T20: ○
B21: 1-6 | E21: 表示 | L21: - | P21: ○ | T21: ○
B22: 1-7 | E22: 次回から自動的にログインする | L22: - | P22: ○ | T22: ○
B23: 1-8 | E23: 新規会員登録はこちら | L23: - | P23: ○ | T23: ○
B24: 1-9 | E24: ログイン | L24: - | P24: ○ | T24: ○

Sheet 画面アクション定義
B2: システムID | H2: =表紙!H5 -> BPS | M2: システム名 | T2: =表紙!T5 -> バトルポータルシュミレーター | AS2: 版数 | AV2: =表紙!N14 -> 1
B3: サブシステムID | H3: =表紙!H6 -> PK | M3: サブシステム名 | T3: =表紙!T6 -> ポータル | AJ3: 作成者 | AM3: =表紙!N10 -> 須賀 | AS3: 更新者 | AV3: =表紙!N12 -> 須賀
B4: 画面ID | H4: =表紙!H7 -> BPSFRPK05 | M4: 画面名 | T4: =表紙!T7 -> 新規会員登録完了 | AJ4: 作成日 | AM4: =表紙!N11 -> 44486 | AS4: 更新者 | AV4: =表紙!N13 -> 44486
B6: 画面アクション定義
B7: 入力・・・画面の入力値/出力・・・画面に出力する項目
B9: ID | D9: アクション名 | J9: 呼び出し条件 | Q9: 処理概要 | AC9: 入出力項目 | AW9: 遷移先画面
AC10: 入力/出力 | AG10: 論理名 | AL10: 物理名 | AQ10: データ型
B11: 1 | D11: 初期表示 | J11: 本画面の初期表示 | Q11: 「BPSBCPK0201_ログイン初期表示処理」を呼び出す。 | AC11: - | AG11: - | AL11: - | AQ11: - | AW11: BPSFRPK02_ログイン
AW12: BPSFRPK07_マイメニュー
B13: 2 | D13: ログインボタン活性/非活性 | J13: ユーザー名またはメールアドレスフォーカスアウト時 | Q13: 以下項目が入力されていれば、ログインボタンを活性にする。 入力されていなければ非活性にする。 ・ユーザ名またはメールアドレス ・パスワード | AC13: - | AG13: - | AL13: - | AQ13: - | AW13: -
B14: 3 | D14: ログインボタン活性/非活性 | J14: パスワードフォーカスアウト時 | Q14: 以下項目が入力されていれば、ログインボタンを活性にする。 入力されていなければ非活性にする。 ・ユーザ名またはメールアドレス ・パスワード | AC14: - | AG14: - | AL14: - | AQ14: - | AW14: -
B15: 4 | D15: パスワード表示 | J15: 表示ボタン押下時 | Q15: 表示ボタン押下時パスワードを表示する。 | AC15: - | AG15: - | AL15: - | AQ15: - | AW15: -
B16: 5 | D16: 新規会員登録遷移 | J16: 新規会員登録ボタン押下時 | Q16: 新規会員登録初期表示処理を呼び出す。 | AC16: - | AG16: - | AL16: - | AQ16: - | AW16: XXXXXX_マイデッキ
B17: 6 | D17: ログイン | J17: ログインボタン 押下時 | Q17: ログイン処理を呼びだす。 | AC17: - | AG17: - | AL17: - | AQ17: - | AW17: ログイン画面
AW18: マイメニュー

Sheet BPSBCPK0101_ログイン初期表示処理
B2: システムID | H2: =表紙!H5 -> BPS | M2: システム名 | T2: =表紙!T5 -> バトルポータルシュミレーター | AS2: 版数 | AV2: =表紙!N14 -> 1
B3: サブシステムID | H3: =表紙!H6 -> PK | M3: サブシステム名 | T3: =表紙!T6 -> ポータル | AJ3: 作成者 | AM3: =表紙!N10 -> 須賀 | AS3: 更新者 | AV3: =表紙!N12 -> 須賀
B4: 画面ID | H4: =表紙!H7 -> BPSFRPK05 | M4: 画面名 | T4: =表紙!T7 -> 新規会員登録完了 | AJ4: 作成日 | AM4: =表紙!N11 -> 44486 | AS4: 更新者 | AV4: =表紙!N13 -> 44486
B6: 処理ID | H6: 処理名称 | W6: パッケージ名 | AB6: jp.co.battlePortalSimulation.controller.pk
B7: BPSBCPK0101 | H7: 共通エリア初期表示処理 | W7: クラス名 | AB7: BPSBCPK0101Servlet | AL7: メソッド名 | AR7: doGet
B9: 処理概要
B10: 共通エリアの初期表示に必要なデータを取得しリクエストに設定する。
B12: 入力項目
B13: 取得元項目 | H13: 論理名 | R13: 物理名 | AG13: データ型 | AO13: 備考
B14: リクエスト | H14: - | R14: - | AG14: - | AO14: -
B16: 出力項目
B17: 出力先項目 | H17: 論理名 | R17: 物理名 | AG17: データ型 | AO17: 備考
B18: リクエスト | H18: - | R18: - | AG18: - | AO18: -
B19: セッション | H19: ログインフラグ | R19: LoginFlag | AG19: String | AO19: 1.ログイン/2.ゲスト
B20: セッション | H20: ログインユーザー | R20: LoginUser | AG20: User | AO20: ログインしているユーザー情報
B22: 遷移先画面
B23: 機能ID | H23: 画面名 | AO23: 備考
B24: BPSFRPK01 | H24: 共通エリア | AO24: -
B26: 処理詳細
B27: 1.セッションから実施処理を判定する。
D29: 処理判別 | S29: 実施処理
D30: セッションがnull or 空 | S30: セッション.ログインフラグ=2.ゲストを設定する。
D31: セッション.ログインユーザーが空orNull | S31: セッション.ログインフラグ=2.ゲストを設定する。
D32: 上記以外 | S32: セッション.ログインフラグ=1.ログインを設定する。
B34: 2.セッション.ログインユーザー.ログインIDからログインユーザーを取得する。
D36: 処理判別 | S36: 実施処理
D37: セッション.ログインフラグ=1.ログイン | S37: 2.1の処理を実施後、3の処理を実施する。
D38: セッション.ログインフラグ=2.ゲスト | S38: 3の処理を実施する。
D40: 2.1.ユーザー取得APIを実行する。
D42: 引数
D43: 論理名 | T43: 物理名 | AC43: データ型 | AO43: 備考
D44: セッション.ログインユーザー.ログインID | T44: loginId | AC44: String | AO44: -
D46: 戻り値
D47: 論理名 | T47: 物理名 | AC47: データ型 | AO47: 備考
D48: ユーザー | T48: user | AC48: User | AO48: -
D50: 2.2.ユーザー取得APIの戻り値をセッションに設定する。
D52: セッション設定値
D53: 論理名 | T53: 物理名 | AC53: データ型 | AO53: 備考
D54: ユーザー | T54: user | AC54: User | AO54: 2.1取得項目
B56: 3.初期表示に必要なデータを取得し、セッションに設定する。
...

Sheet BPSBCPK0102_ログイン処理
B2: システムID | H2: =表紙!H5 -> BPS | M2: システム名 | T2: =表紙!T5 -> バトルポータルシュミレーター | AS2: 版数 | AV2: =表紙!N14 -> 1
B3: サブシステムID | H3: =表紙!H6 -> PK | M3: サブシステム名 | T3: =表紙!T6 -> ポータル | AJ3: 作成者 | AM3: =表紙!N10 -> 須賀 | AS3: 更新者 | AV3: =表紙!N12 -> 須賀
B4: 画面ID | H4: =表紙!H7 -> BPSFRPK05 | M4: 画面名 | T4: =表紙!T7 -> 新規会員登録完了 | AJ4: 作成日 | AM4: =表紙!N11 -> 44486 | AS4: 更新者 | AV4: =表紙!N13 -> 44486
B6: 処理ID | H6: 処理名称 | W6: パッケージ名 | AB6: jp.co.battlePortalSimulation.controller.pk
B7: BPSBCPK0101 | H7: ログアウト処理 | W7: クラス名 | AB7: BPSBCPK0101Servlet | AL7: メソッド名 | AR7: doGet
B9: 処理概要
B10: 共通エリアの初期表示に必要な情報を取得する処理
B12: 入力項目
B13: 取得元項目 | H13: 論理名 | R13: 物理名 | AG13: データ型 | AO13: 備考
B14: リクエスト | H14: - | R14: - | AG14: - | AO14: -
B16: 出力項目
B17: 出力先項目 | H17: 論理名 | R17: 物理名 | AG17: データ型 | AO17: 備考
B18: リクエスト | H18: - | R18: - | AG18: - | AO18: -
B19: セッション | H19: ログインフラグ | R19: LoginFlag | AG19: String | AO19: 1.ログイン/2.ゲスト
B20: セッション | H20: ログインユーザー | R20: LoginUser | AG20: User | AO20: ログインしているユーザー情報
B23: 処理詳細
B24: 1.セッション.ログインユーザーから実施処理を判別する。
D26: 処理判別 | S26: 実施処理
D27: セッション.ログインユーザーが空orNull | S27: セッション.ログインフラグ=2.ゲストを設定する。
D28: 上記以外 | S28: セッション.ログインフラグ=1.ログインを設定する。
B30: 2.セッション.ログインユーザー.ログインIDからログインユーザーを取得する。
D32: 処理判別 | S32: 実施処理
D33: セッション.ログインフラグ=1.ログイン | S33: 2.1の処理を実施する。
D34: セッション.ログインフラグ=2.ゲスト | S34: 以下の処理を実施する。
D36: 2.1.ユーザー取得APIを実行する。
D38: 引数
D39: 論理名 | T39: 物理名 | AC39: データ型 | AO39: 備考
D40: セッション.ログインユーザー.ログインID | T40: loginId | AC40: String | AO40: -
D42: 戻り値
D43: 論理名 | T43: 物理名 | AC43: データ型 | AO43: 備考
D44: ユーザー | T44: user | AC44: User | AO44: -
D46: 2.2.ユーザー取得APIの戻り値をセッションに設定する。
