Workbook

Sheet 表紙
B3: 画面レイアウト
B5: システムID | H5: BSPS | M5: システム名 | T5: バトルシミレーションポータルサイト
B6: サブシステムID | H6: PK | M6: サブシステム名 | T6: ポータル
B7: 画面ID | H7: - | M7: 画面名 | T7: -
B10: 作成者 | N10: =改訂履歴!AS9 -> 須賀
B11: 作成日 | N11: =改訂履歴!E9 -> 44440
B12: 更新者 | N12: =VLOOKUP(表紙!N14,改訂履歴!B:AS,44,FALSE) -> 須賀
B13: 更新日 | N13: =VLOOKUP(表紙!N14,改訂履歴!B:E,4,FALSE) -> 44518
B14: 版数 | N14: =MAX(改訂履歴!B:B) -> 1.7

Sheet 改訂履歴
B2: システムID | H2: =表紙!H5 -> BSPS | M2: システム名 | T2: =表紙!T5 -> バトルシミレーションポータルサイト | AS2: 版数 | AV2: =表紙!N14 -> 1.7
B3: サブシステムID | H3: =表紙!H6 -> PK | M3: サブシステム名 | T3: =表紙!T6 -> ポータル | AJ3: 作成者 | AM3: =表紙!N10 -> 須賀 | AS3: 更新者 | AV3: =表紙!N12 -> 須賀
B4: 画面ID | H4: =表紙!H7 -> - | M4: 画面名 | T4: =表紙!T7 -> - | AJ4: 作成日 | AM4: =表紙!N11 -> 44440 | AS4: 更新者 | AV4: =表紙!N13 -> 44518
B6: 改訂履歴
B8: 版数 | E8: 改定日 | I8: 改定シート | W8: 改定内容 | AS8: 担当
B9: 1 | E9: 44440 | I9: 全般 | W9: 新規作成 | AS9: 須賀
B10: 1.1 | E10: 44454 | I10: BSPSFRPK03_新規会員登録入力 BSPSFRPK03_新規会員登録入力_メッセージ表示 BSPSFRPK04_新規会員登録確認 BSPSFRPPK05_新規会員登完了 | W10: 新規作成 | AS10: 須賀
B11: 1.2 | E11: 44460 | I11: BSPSFRPK06_パスワード再発行 BSPSFRPK06_パスワード再発行_メッセージ表示 BSPSFRPK07_パスワード再発行完了 | W11: 新規作成 | AS11: 須賀
B12: 1.3 | E12: 44470 | I12: BSPSFRPK08_マイメニュー | W12: 新規作成 | AS12: 須賀
B13: 1.4 | E13: 44484 | I13: BSPSFRPK09_お知らせ・通知一覧 BSPSFRPK10_お知らせ・通知詳細 | W13: 新規作成 | AS13: 須賀
B14: 1.5 | E14: 44501 | I14: BSPSFRPK11_対戦履歴 BSPSFRPK12_対戦履歴詳細 | W14: 新規作成 | AS14: 須賀
B15: 1.6 | E15: 44513 | I15: BSPSFRPK13_マイデッキ BSPSFRPK14_マイフレンド BSPSFRPK15_チャット BSPSFRPK16_フレンド追加 | W15: 新規作成 | AS15: 須賀
B16: 1.7 | E16: 44518 | I16: BSPSFRPK17_マイプロフィール | W16: 新規作成 | AS16: 須賀

Sheet 概要
B2: システムID | H2: =表紙!H5 -> BSPS | M2: システム名 | T2: =表紙!T5 -> バトルシミレーションポータルサイト | AS2: 版数 | AV2: =表紙!N14 -> 1.7
B3: サブシステムID | H3: =表紙!H6 -> PK | M3: サブシステム名 | T3: =表紙!T6 -> ポータル | AJ3: 作成者 | AM3: =表紙!N10 -> 須賀 | AS3: 更新者 | AV3: =表紙!N12 -> 須賀
B4: 画面ID | H4: =表紙!H7 -> - | M4: 画面名 | T4: =表紙!T7 -> - | AJ4: 作成日 | AM4: =表紙!N11 -> 44440 | AS4: 更新者 | AV4: =表紙!N13 -> 44518
B6: 概要
B7: ◆本資料の位置づけ
C8: 本資料は画面のレイアウトを記載し、画面構成と他画面との繋がりを直観的にわかるようにするための資料とする。
B11: ◆画面遷移フロー
C12: ※機能一覧・画面遷移図を参照

Sheet BSPSFRPK01_共通エリア_未ログイン
B2: システムID | H2: =表紙!H5 -> BSPS | M2: システム名 | T2: =表紙!T5 -> バトルシミレーションポータルサイト | AS2: 版数 | AV2: =表紙!N14 -> 1.7
B3: サブシステムID | H3: =表紙!H6 -> PK | M3: サブシステム名 | T3: =表紙!T6 -> ポータル | AJ3: 作成者 | AM3: =表紙!N10 -> 須賀 | AS3: 更新者 | AV3: =表紙!N12 -> 須賀
B4: 画面ID | H4: BSPSFRPK01 | M4: 画面名 | T4: 共通エリア | AJ4: 作成日 | AM4: =表紙!N11 -> 44440 | AS4: 更新者 | AV4: =表紙!N13 -> 44518
B6: 表示条件
B7: １．初期表示_未ログイン
B9: 画面レイアウト（PC）

Sheet BSPSFRPK01_共通エリア_ログイン時
B2: システムID | H2: =表紙!H5 -> BSPS | M2: システム名 | T2: =表紙!T5 -> バトルシミレーションポータルサイト | AS2: 版数 | AV2: =表紙!N14 -> 1.7
B3: サブシステムID | H3: =表紙!H6 -> PK | M3: サブシステム名 | T3: =表紙!T6 -> ポータル | AJ3: 作成者 | AM3: =表紙!N10 -> 須賀 | AS3: 更新者 | AV3: =表紙!N12 -> 須賀
B4: 画面ID | H4: BSPSFRPK01 | M4: 画面名 | T4: 共通エリア | AJ4: 作成日 | AM4: =表紙!N11 -> 44440 | AS4: 更新者 | AV4: =表紙!N13 -> 44518
B6: 表示条件
B7: ２．初期表示_ログイン時
B9: 画面レイアウト（PC）

Sheet BSPSFRPK01_共通エリア_ユーザーメニュー
B2: システムID | H2: =表紙!H5 -> BSPS | M2: システム名 | T2: =表紙!T5 -> バトルシミレーションポータルサイト | AS2: 版数 | AV2: =表紙!N14 -> 1.7
B3: サブシステムID | H3: =表紙!H6 -> PK | M3: サブシステム名 | T3: =表紙!T6 -> ポータル | AJ3: 作成者 | AM3: =表紙!N10 -> 須賀 | AS3: 更新者 | AV3: =表紙!N12 -> 須賀
B4: 画面ID | H4: BSPSFRPK01 | M4: 画面名 | T4: 共通エリア | AJ4: 作成日 | AM4: =表紙!N11 -> 44440 | AS4: 更新者 | AV4: =表紙!N13 -> 44518
B6: 表示条件
B7: ３．ハンバーガーメニュー
B9: 画面レイアウト（PC）

Sheet BSPSFRPK01_共通エリア_カード詳細検索
B2: システムID | H2: =表紙!H5 -> BSPS | M2: システム名 | T2: =表紙!T5 -> バトルシミレーションポータルサイト | AS2: 版数 | AV2: =表紙!N14 -> 1.7
B3: サブシステムID | H3: =表紙!H6 -> PK | M3: サブシステム名 | T3: =表紙!T6 -> ポータル | AJ3: 作成者 | AM3: =表紙!N10 -> 須賀 | AS3: 更新者 | AV3: =表紙!N12 -> 須賀
B4: 画面ID | H4: BSPSFRPK01 | M4: 画面名 | T4: 共通エリア | AJ4: 作成日 | AM4: =表紙!N11 -> 44440 | AS4: 更新者 | AV4: =表紙!N13 -> 44518
B6: 表示条件
B7: ４．カード詳細検索
B9: 画面レイアウト（PC）

Sheet BSPSFRPK02_ログイン
B2: システムID | H2: =表紙!H5 -> BSPS | M2: システム名 | T2: =表紙!T5 -> バトルシミレーションポータルサイト | AS2: 版数 | AV2: =表紙!N14 -> 1.7
B3: サブシステムID | H3: =表紙!H6 -> PK | M3: サブシステム名 | T3: =表紙!T6 -> ポータル | AJ3: 作成者 | AM3: =表紙!N10 -> 須賀 | AS3: 更新者 | AV3: =表紙!N12 -> 須賀
B4: 画面ID | H4: BSPSFRPK02 | M4: 画面名 | T4: ログイン | AJ4: 作成日 | AM4: =表紙!N11 -> 44440 | AS4: 更新者 | AV4: =表紙!N13 -> 44518
B6: 表示条件
B7: １．初期表示
B9: 画面レイアウト（PC）

Sheet BSPSFRPK02_ログイン_メッセージ表示
B2: システムID | H2: =表紙!H5 -> BSPS | M2: システム名 | T2: =表紙!T5 -> バトルシミレーションポータルサイト | AS2: 版数 | AV2: =表紙!N14 -> 1.7
B3: サブシステムID | H3: =表紙!H6 -> PK | M3: サブシステム名 | T3: =表紙!T6 -> ポータル | AJ3: 作成者 | AM3: =表紙!N10 -> 須賀 | AS3: 更新者 | AV3: =表紙!N12 -> 須賀
B4: 画面ID | H4: BSPSFRPK02 | M4: 画面名 | T4: ログイン | AJ4: 作成日 | AM4: =表紙!N11 -> 44440 | AS4: 更新者 | AV4: =表紙!N13 -> 44518
B6: 表示条件
B7: １．初期表示_メッセージ表示
B9: 画面レイアウト（PC）

Sheet BSPSFRPK03_新規会員登録入力
B2: システムID | H2: =表紙!H5 -> BSPS | M2: システム名 | T2: =表紙!T5 -> バトルシミレーションポータルサイト | AS2: 版数 | AV2: =表紙!N14 -> 1.7
B3: サブシステムID | H3: =表紙!H6 -> PK | M3: サブシステム名 | T3: =表紙!T6 -> ポータル | AJ3: 作成者 | AM3: =表紙!N10 -> 須賀 | AS3: 更新者 | AV3: =表紙!N12 -> 須賀
B4: 画面ID | H4: BSPSFRPK03 | M4: 画面名 | T4: 新規会員登録入力 | AJ4: 作成日 | AM4: =表紙!N11 -> 44440 | AS4: 更新者 | AV4: =表紙!N13 -> 44518
B6: 表示条件
B7: １．初期表示_未ログイン
B9: 画面レイアウト（PC）

Sheet BSPSFRPK03_新規会員登録入力_メッセージ表示
B2: システムID | H2: =表紙!H5 -> BSPS | M2: システム名 | T2: =表紙!T5 -> バトルシミレーションポータルサイト | AS2: 版数 | AV2: =表紙!N14 -> 1.7
B3: サブシステムID | H3: =表紙!H6 -> PK | M3: サブシステム名 | T3: =表紙!T6 -> ポータル | AJ3: 作成者 | AM3: =表紙!N10 -> 須賀 | AS3: 更新者 | AV3: =表紙!N12 -> 須賀
B4: 画面ID | H4: BSPSFRPK03 | M4: 画面名 | T4: 新規会員登録入力 | AJ4: 作成日 | AM4: =表紙!N11 -> 44440 | AS4: 更新者 | AV4: =表紙!N13 -> 44518
B6: 表示条件
B7: １．メッセージ表示
B9: 画面レイアウト（PC）

Sheet BSPSFRPK04_新規会員登録確認
B2: システムID | H2: =表紙!H5 -> BSPS | M2: システム名 | T2: =表紙!T5 -> バトルシミレーションポータルサイト | AS2: 版数 | AV2: =表紙!N14 -> 1.7
B3: サブシステムID | H3: =表紙!H6 -> PK | M3: サブシステム名 | T3: =表紙!T6 -> ポータル | AJ3: 作成者 | AM3: =表紙!N10 -> 須賀 | AS3: 更新者 | AV3: =表紙!N12 -> 須賀
B4: 画面ID | H4: BSPSFRPK04 | M4: 画面名 | T4: 新規会員登録確認 | AJ4: 作成日 | AM4: =表紙!N11 -> 44440 | AS4: 更新者 | AV4: =表紙!N13 -> 44518
B6: 表示条件
B7: １．初期表示_未ログイン
B9: 画面レイアウト（PC）

Sheet BSPSFRPPK05_新規会員登完了
B2: システムID | H2: =表紙!H5 -> BSPS | M2: システム名 | T2: =表紙!T5 -> バトルシミレーションポータルサイト | AS2: 版数 | AV2: =表紙!N14 -> 1.7
B3: サブシステムID | H3: =表紙!H6 -> PK | M3: サブシステム名 | T3: =表紙!T6 -> ポータル | AJ3: 作成者 | AM3: =表紙!N10 -> 須賀 | AS3: 更新者 | AV3: =表紙!N12 -> 須賀
B4: 画面ID | H4: BSPSFRPPK05 | M4: 画面名 | T4: 新規会員登録完了 | AJ4: 作成日 | AM4: =表紙!N11 -> 44440 | AS4: 更新者 | AV4: =表紙!N13 -> 44518
B6: 表示条件
B7: １．初期表示_未ログイン
B9: 画面レイアウト（PC）

Sheet BSPSFRPK06_パスワード再発行
B2: システムID | H2: =表紙!H5 -> BSPS | M2: システム名 | T2: =表紙!T5 -> バトルシミレーションポータルサイト | AS2: 版数 | AV2: =表紙!N14 -> 1.7
B3: サブシステムID | H3: =表紙!H6 -> PK | M3: サブシステム名 | T3: =表紙!T6 -> ポータル | AJ3: 作成者 | AM3: =表紙!N10 -> 須賀 | AS3: 更新者 | AV3: =表紙!N12 -> 須賀
B4: 画面ID | H4: BSPSFRPK06 | M4: 画面名 | T4: パスワード再発行 | AJ4: 作成日 | AM4: =表紙!N11 -> 44440 | AS4: 更新者 | AV4: =表紙!N13 -> 44518
B6: 表示条件
B7: １．初期表示
B9: 画面レイアウト（PC）

Sheet BSPSFRPK06_パスワード再発行_メッセージ表示
B2: システムID | H2: =表紙!H5 -> BSPS | M2: システム名 | T2: =表紙!T5 -> バトルシミレーションポータルサイト | AS2: 版数 | AV2: =表紙!N14 -> 1.7
B3: サブシステムID | H3: =表紙!H6 -> PK | M3: サブシステム名 | T3: =表紙!T6 -> ポータル | AJ3: 作成者 | AM3: =表紙!N10 -> 須賀 | AS3: 更新者 | AV3: =表紙!N12 -> 須賀
B4: 画面ID | H4: BSPSFRPK06 | M4: 画面名 | T4: パスワード再発行 | AJ4: 作成日 | AM4: =表紙!N11 -> 44440 | AS4: 更新者 | AV4: =表紙!N13 -> 44518
B6: 表示条件
B7: ２．メッセージ表示
B9: 画面レイアウト（PC）

Sheet BSPSFRPK07_パスワード再発行完了
B2: システムID | H2: =表紙!H5 -> BSPS | M2: システム名 | T2: =表紙!T5 -> バトルシミレーションポータルサイト | AS2: 版数 | AV2: =表紙!N14 -> 1.7
B3: サブシステムID | H3: =表紙!H6 -> PK | M3: サブシステム名 | T3: =表紙!T6 -> ポータル | AJ3: 作成者 | AM3: =表紙!N10 -> 須賀 | AS3: 更新者 | AV3: =表紙!N12 -> 須賀
B4: 画面ID | H4: BSPSFRPK07 | M4: 画面名 | T4: パスワード再発行完了 | AJ4: 作成日 | AM4: =表紙!N11 -> 44440 | AS4: 更新者 | AV4: =表紙!N13 -> 44518
B6: 表示条件
B7: １．初期表示
B9: 画面レイアウト（PC）

Sheet BSPSFRPK08_マイメニュー
B2: システムID | H2: =表紙!H5 -> BSPS | M2: システム名 | T2: =表紙!T5 -> バトルシミレーションポータルサイト | AS2: 版数 | AV2: =表紙!N14 -> 1.7
B3: サブシステムID | H3: =表紙!H6 -> PK | M3: サブシステム名 | T3: =表紙!T6 -> ポータル | AJ3: 作成者 | AM3: =表紙!N10 -> 須賀 | AS3: 更新者 | AV3: =表紙!N12 -> 須賀
B4: 画面ID | H4: BSPSFRPK08 | M4: 画面名 | T4: マイメニュー | AJ4: 作成日 | AM4: =表紙!N11 -> 44440 | AS4: 更新者 | AV4: =表紙!N13 -> 44518
B6: 表示条件
B7: １．初期表示
B9: 画面レイアウト（PC）

Sheet BSPSFRPK09_お知らせ・通知一覧
B2: システムID | H2: =表紙!H5 -> BSPS | M2: システム名 | T2: =表紙!T5 -> バトルシミレーションポータルサイト | AS2: 版数 | AV2: =表紙!N14 -> 1.7
B3: サブシステムID | H3: =表紙!H6 -> PK | M3: サブシステム名 | T3: =表紙!T6 -> ポータル | AJ3: 作成者 | AM3: =表紙!N10 -> 須賀 | AS3: 更新者 | AV3: =表紙!N12 -> 須賀
B4: 画面ID | H4: BSPSFRPK09 | M4: 画面名 | T4: お知らせ・通知一覧 | AJ4: 作成日 | AM4: =表紙!N11 -> 44440 | AS4: 更新者 | AV4: =表紙!N13 -> 44518
B6: 表示条件
B7: １．初期表示
B9: 画面レイアウト（PC）

Sheet BSPSFRPK10_お知らせ・通知詳細
B2: システムID | H2: =表紙!H5 -> BSPS | M2: システム名 | T2: =表紙!T5 -> バトルシミレーションポータルサイト | AS2: 版数 | AV2: =表紙!N14 -> 1.7
B3: サブシステムID | H3: =表紙!H6 -> PK | M3: サブシステム名 | T3: =表紙!T6 -> ポータル | AJ3: 作成者 | AM3: =表紙!N10 -> 須賀 | AS3: 更新者 | AV3: =表紙!N12 -> 須賀
B4: 画面ID | H4: BSPSFRPK10 | M4: 画面名 | T4: お知らせ・通知詳細 | AJ4: 作成日 | AM4: =表紙!N11 -> 44440 | AS4: 更新者 | AV4: =表紙!N13 -> 44518
B6: 表示条件
B7: １．初期表示
B9: 画面レイアウト（PC）

Sheet BSPSFRPK11_対戦履歴一覧
B2: システムID | H2: =表紙!H5 -> BSPS | M2: システム名 | T2: =表紙!T5 -> バトルシミレーションポータルサイト | AS2: 版数 | AV2: =表紙!N14 -> 1.7
B3: サブシステムID | H3: =表紙!H6 -> PK | M3: サブシステム名 | T3: =表紙!T6 -> ポータル | AJ3: 作成者 | AM3: =表紙!N10 -> 須賀 | AS3: 更新者 | AV3: =表紙!N12 -> 須賀
B4: 画面ID | H4: BSPSFRPK11 | M4: 画面名 | T4: 対戦履歴一覧 | AJ4: 作成日 | AM4: =表紙!N11 -> 44440 | AS4: 更新者 | AV4: =表紙!N13 -> 44518
B6: 表示条件
B7: １．初期表示
B9: 画面レイアウト（PC）

Sheet BSPSFRPK12_対戦履歴詳細
B2: システムID | H2: =表紙!H5 -> BSPS | M2: システム名 | T2: =表紙!T5 -> バトルシミレーションポータルサイト | AS2: 版数 | AV2: =表紙!N14 -> 1.7
B3: サブシステムID | H3: =表紙!H6 -> PK | M3: サブシステム名 | T3: =表紙!T6 -> ポータル | AJ3: 作成者 | AM3: =表紙!N10 -> 須賀 | AS3: 更新者 | AV3: =表紙!N12 -> 須賀
B4: 画面ID | H4: BSPSFRPK12 | M4: 画面名 | T4: 対戦履歴詳細 | AJ4: 作成日 | AM4: =表紙!N11 -> 44440 | AS4: 更新者 | AV4: =表紙!N13 -> 44518
B6: 表示条件
B7: １．初期表示
B9: 画面レイアウト（PC）
C23: あなたが使用したデッキ
C24: カード名 | N24: カード種類 | S24: 色 | U24: レベル | X24: コスト | AA24: 枚数
C25: ○○なゆうこりん | N25: Chara | S25: 赤 | U25: 0 | X25: 0 | AA25: 1枚
C26: 一番の宝物 | N26: EV | S26: 赤 | U26: 0 | X26: 0 | AA26: 2枚
C27: 崩壊の足音 | N27: CX | S27: 青 | U27: 1 | X27: 1 | AA27: 4枚
C29: 相手が使用したデッキ
C30: カード名 | N30: カード種類 | S30: 色 | U30: レベル | X30: コスト | AA30: 枚数
C31: ○○なゆうこりん | N31: Chara | S31: 赤 | U31: 0 | X31: 0 | AA31: 1枚
C32: 一番の宝物 | N32: EV | S32: 赤 | U32: 0 | X32: 0 | AA32: 2枚
C33: 崩壊の足音 | N33: CX | S33: 青 | U33: 1 | X33: 1 | AA33: 4枚
C34: ○○なゆうこりん | N34: Chara | S34: 赤 | U34: 0 | X34: 0 | AA34: 1枚
C35: 一番の宝物 | N35: EV | S35: 赤 | U35: 0 | X35: 0 | AA35: 2枚
C36: 崩壊の足音 | N36: CX | S36: 青 | U36: 1 | X36: 1 | AA36: 4枚
C37: ○○なゆうこりん | N37: Chara | S37: 赤 | U37: 0 | X37: 0 | AA37: 1枚
C38: 一番の宝物 | N38: EV | S38: 赤 | U38: 0 | X38: 0 | AA38: 2枚
C39: 崩壊の足音 | N39: CX | S39: 青 | U39: 1 | X39: 1 | AA39: 4枚
C40: ○○なゆうこりん | N40: Chara | S40: 赤 | U40: 0 | X40: 0 | AA40: 1枚
C41: 一番の宝物 | N41: EV | S41: 赤 | U41: 0 | X41: 0 | AA41: 2枚
C42: 崩壊の足音 | N42: CX | S42: 青 | U42: 1 | X42: 1 | AA42: 4枚
C45: 対戦ログ
C46: ターン数 | AF46: レベル-クロック
C47: １ターン目 相手のターン | AF47: あなた 0-1 相手 0-3
C48: ２ターン目 あなたのターン | AF48: あなた 0-6 相手 0-4
C49: ３ターン目 相手のターン | AF49: あなた 1-0 相手 1-2
D50: スタンドフェイズ | AG50: あなた 1-0 相手 1-2
E51: スタンドする。
D52: ドローフェイズ | AG52: あなた 1-0 相手 1-2
E53: 1枚ドローする。
D54: クロックフェイズ | AG54: あなた 1-0 相手 1-2
D55: メインフェイズ | AG55: あなた 1-0 相手 1-2
D56: クライマックスフェイズ | AG56: あなた 1-0 相手 1-2
D57: アタックフェイズ | AG57: あなた 1-0 相手 1-2
D58: エンドフェイズ | AG58: あなた 1-0 相手 1-2
C59: ４ターン目 あなたのターン | AF59: あなた 1-5 相手 1-3
...

Sheet BSPSFRPK13_マイデッキ
B2: システムID | H2: =表紙!H5 -> BSPS | M2: システム名 | T2: =表紙!T5 -> バトルシミレーションポータルサイト | AS2: 版数 | AV2: =表紙!N14 -> 1.7
B3: サブシステムID | H3: =表紙!H6 -> PK | M3: サブシステム名 | T3: =表紙!T6 -> ポータル | AJ3: 作成者 | AM3: =表紙!N10 -> 須賀 | AS3: 更新者 | AV3: =表紙!N12 -> 須賀
B4: 画面ID | H4: BSPSFRPK13 | M4: 画面名 | T4: マイデッキ | AJ4: 作成日 | AM4: =表紙!N11 -> 44440 | AS4: 更新者 | AV4: =表紙!N13 -> 44518
B6: 表示条件
B7: １．初期表示
B9: 画面レイアウト（PC）

Sheet BSPSFRPK14_マイフレンド
B2: システムID | H2: =表紙!H5 -> BSPS | M2: システム名 | T2: =表紙!T5 -> バトルシミレーションポータルサイト | AS2: 版数 | AV2: =表紙!N14 -> 1.7
B3: サブシステムID | H3: =表紙!H6 -> PK | M3: サブシステム名 | T3: =表紙!T6 -> ポータル | AJ3: 作成者 | AM3: =表紙!N10 -> 須賀 | AS3: 更新者 | AV3: =表紙!N12 -> 須賀
B4: 画面ID | H4: BSPSFRPK14 | M4: 画面名 | T4: マイフレンド | AJ4: 作成日 | AM4: =表紙!N11 -> 44440 | AS4: 更新者 | AV4: =表紙!N13 -> 44518
B6: 表示条件
B7: １．初期表示
B9: 画面レイアウト（PC）

Sheet BSPSFRPK15_チャット
B2: システムID | H2: =表紙!H5 -> BSPS | M2: システム名 | T2: =表紙!T5 -> バトルシミレーションポータルサイト | AS2: 版数 | AV2: =表紙!N14 -> 1.7
B3: サブシステムID | H3: =表紙!H6 -> PK | M3: サブシステム名 | T3: =表紙!T6 -> ポータル | AJ3: 作成者 | AM3: =表紙!N10 -> 須賀 | AS3: 更新者 | AV3: =表紙!N12 -> 須賀
B4: 画面ID | H4: BSPSFRPK15 | M4: 画面名 | T4: チャット | AJ4: 作成日 | AM4: =表紙!N11 -> 44440 | AS4: 更新者 | AV4: =表紙!N13 -> 44518
B6: 表示条件
B7: １．初期表示
B9: 画面レイアウト（PC）

Sheet BSPSFRPK16_フレンド追加
B2: システムID | H2: =表紙!H5 -> BSPS | M2: システム名 | T2: =表紙!T5 -> バトルシミレーションポータルサイト | AS2: 版数 | AV2: =表紙!N14 -> 1.7
B3: サブシステムID | H3: =表紙!H6 -> PK | M3: サブシステム名 | T3: =表紙!T6 -> ポータル | AJ3: 作成者 | AM3: =表紙!N10 -> 須賀 | AS3: 更新者 | AV3: =表紙!N12 -> 須賀
B4: 画面ID | H4: BSPSFRPK16 | M4: 画面名 | T4: フレンド追加 | AJ4: 作成日 | AM4: =表紙!N11 -> 44440 | AS4: 更新者 | AV4: =表紙!N13 -> 44518
B6: 表示条件
B7: １．初期表示
B9: 画面レイアウト（PC）

Sheet BSPSFRPK17_マイプロフィール
B2: システムID | H2: =表紙!H5 -> BSPS | M2: システム名 | T2: =表紙!T5 -> バトルシミレーションポータルサイト | AS2: 版数 | AV2: =表紙!N14 -> 1.7
B3: サブシステムID | H3: =表紙!H6 -> PK | M3: サブシステム名 | T3: =表紙!T6 -> ポータル | AJ3: 作成者 | AM3: =表紙!N10 -> 須賀 | AS3: 更新者 | AV3: =表紙!N12 -> 須賀
B4: 画面ID | H4: BSPSFRPK17 | M4: 画面名 | T4: マイプロフィール | AJ4: 作成日 | AM4: =表紙!N11 -> 44440 | AS4: 更新者 | AV4: =表紙!N13 -> 44518
B6: 表示条件
B7: １．初期表示_未ログイン
B9: 画面レイアウト（PC）
