Workbook

Sheet 表紙
B3: 命名規約
B5: システムID | H5: BSPS | M5: システム名 | T5: バトルシミレーションポータルサイト
B6: サブシステムID | H6: - | M6: サブシステム名 | T6: -
B7: 画面ID | H7: - | M7: 画面名 | T7: -
B10: 作成者 | N10: =改訂履歴!AS9 -> 須賀
B11: 作成日 | N11: =改訂履歴!E9 -> 44465
B12: 更新者 | N12: =VLOOKUP(表紙!N14,改訂履歴!B:AS,44,FALSE) -> 須賀
B13: 更新日 | N13: =VLOOKUP(表紙!N14,改訂履歴!B:E,4,FALSE) -> 44465
B14: 版数 | N14: =MAX(改訂履歴!B:B) -> 1

Sheet 改訂履歴
B2: システムID | H2: =表紙!H5 -> BSPS | M2: システム名 | T2: =表紙!T5 -> バトルシミレーションポータルサイト | AS2: 版数 | AV2: =表紙!N14 -> 1
B3: サブシステムID | H3: =表紙!H6 -> - | M3: サブシステム名 | T3: =表紙!T6 -> - | AJ3: 作成者 | AM3: =表紙!N10 -> 須賀 | AS3: 更新者 | AV3: =表紙!N12 -> 須賀
B4: 画面ID | H4: =表紙!H7 -> - | M4: 画面名 | T4: =表紙!T7 -> - | AJ4: 作成日 | AM4: =表紙!N11 -> 44465 | AS4: 更新者 | AV4: =表紙!N13 -> 44465
B6: 改訂履歴
B8: 版数 | E8: 改定日 | I8: 改定シート | P8: 改定内容 | AS8: 担当
B9: 1 | E9: 44465 | I9: 全般 | P9: 新規作成 | AS9: 須賀

Sheet 命名規約
B2: システムID | H2: =表紙!H5 -> BSPS | M2: システム名 | T2: =表紙!T5 -> バトルシミレーションポータルサイト | AS2: 版数 | AV2: =表紙!N14 -> 1
B3: サブシステムID | H3: =表紙!H6 -> - | M3: サブシステム名 | T3: =表紙!T6 -> - | AJ3: 作成者 | AM3: =表紙!N10 -> 須賀 | AS3: 更新者 | AV3: =表紙!N12 -> 須賀
B4: 画面ID | H4: =表紙!H7 -> - | M4: 画面名 | T4: =表紙!T7 -> - | AJ4: 作成日 | AM4: =表紙!N11 -> 44465 | AS4: 更新者 | AV4: =表紙!N13 -> 44465
B6: 命名規約
B9: 画面ID
B10: No | E10: 項目 | L10: タイプ
B12: 1 | E12: システムID | L12: -
B13: 1-1 | E13: BSPS | L13: バトルシミレーションポータルサイト
B14: 2 | E14: サブシステムID | L14: -
B15: 2-1 | E15: PK | L15: ポータル機能
B16: 2-2 | E16: CD | L16: カードデッキ構築機能
B17: 2-3 | E17: CB | L17: CPU対戦機能
B18: 2-4 | E18: OB | L18: オンライン対戦機能
B19: 3 | E19: 種別ID | L19: -
B20: 3-1 | E20: FR | L20: 画面
B21: 4 | E21: 機能連番 | L21: -
B22: 4-1 | E22: 01～99 | L22: 画面の識別番号
B24: バックエンド処理ID
B25: No | E25: 項目 | L25: タイプ
B27: 1 | E27: システムID | L27: -
B28: 1-1 | E28: BSPS | L28: バトルシミレーションポータルサイト
B29: 2 | E29: サブシステムID | L29: -
B30: 2-1 | E30: PK | L30: ポータル機能
B31: 2-2 | E31: CD | L31: カードデッキ構築機能
B32: 2-3 | E32: CB | L32: CPU対戦機能
B33: 2-4 | E33: OB | L33: オンライン対戦機能
B34: 3 | E34: 種別ID | L34: -
B35: 3-1 | E35: FR | L35: 画面
B36: 4 | E36: 機能連番 | L36: -
B37: 4-1 | E37: 01～99 | L37: 画面の識別番号
... B42: 6-1 | E42: 01～99 | L42: 処理の識別番号
B44: 共通処理ID
B45: No | E45: 項目 | L45: タイプ
B47: 1 | E47: システムID | L47: -
B48: 1-1 | E48: BSPS | L48: バトルシミレーションポータルサイト
B49: 2 | E49: サブシステムID | L49: -
B50: 2-1 | E50: PK | L50: ポータル機能
B51: 2-2 | E51: CD | L51: カードデッキ構築機能
B52: 2-3 | E52: CB | L52: CPU対戦機能
B53: 2-4 | E53: OB | L53: オンライン対戦機能
...
