Workbook

Sheet 表紙
B3: 機能一覧・画面遷移図
B5: システムID | H5: BSPS | M5: システム名 | T5: バトルシミレーションポータルサイト
B6: サブシステムID | H6: - | M6: サブシステム名 | T6: -
B7: 機能ID | H7: - | M7: 機能名 | T7: -
B10: 作成者 | N10: =改訂履歴!AS9 -> 須賀
B11: 作成日 | N11: =改訂履歴!E9 -> 44464
B12: 更新者 | N12: =VLOOKUP(表紙!N14,改訂履歴!B:AS,44,FALSE) -> 須賀
B13: 更新日 | N13: =VLOOKUP(表紙!N14,改訂履歴!B:E,4,FALSE) -> 44520
B14: 版数 | N14: =MAX(改訂履歴!B:B) -> 1.4

Sheet 改訂履歴
B2: システムID | H2: =表紙!H5 -> BSPS | M2: システム名 | T2: =表紙!T5 -> バトルシミレーションポータルサイト | AS2: 版数 | AV2: =表紙!N14 -> 1.4
B3: サブシステムID | H3: =表紙!H6 -> - | M3: サブシステム名 | T3: =表紙!T6 -> - | AJ3: 作成者 | AM3: =表紙!N10 -> 須賀 | AS3: 更新者 | AV3: =表紙!N12 -> 須賀
B4: 機能ID | H4: =表紙!H7 -> - | M4: 機能名 | T4: =表紙!T7 -> - | AJ4: 作成日 | AM4: =表紙!N11 -> 44464 | AS4: 更新者 | AV4: =表紙!N13 -> 44520
B6: 改訂履歴
B8: 版数 | E8: 改定日 | K8: 改定シート | V8: 改定内容 | AS8: 担当
B9: 1 | E9: 44464 | K9: 全般 | V9: 新規作成 | AS9: 須賀
B10: 1.1 | E10: 44477 | K10: 画面一覧 | V10: ポータル機能分作成 | AS10: 須賀
B11: 1.2 | E11: 44477 | K11: 画面遷移図 | V11: ポータル機能分更新 | AS11: 須賀
B12: 1.3 | E12: 44518 | K12: 画面一覧、画面遷移図 | V12: ポータル機能分更新 | AS12: 須賀
B13: 1.4 | E13: 44520 | K13: 表紙、機能一覧 | V13: 画面遷移図⇒機能関連図に修正 画面一覧⇒機能一覧に修正 | AS13: 須賀

Sheet 画面一覧
B2: 画面一覧
B4: 業務分類 | C4: 機能分類 | D4: 機能ID | E4: 機能名 | F4: ファイル名 | G4: 備考
B5: ポータル | C5: 画面 | D5: BSPSFRPK01 | E5: 共通エリア | F5: BSPSFRPK01.jsp | G5: 全画面共通のエリア
B6: ポータル | C6: 画面 | D6: BSPSFRPK02 | E6: ログイン | F6: BSPSFRPK02.jsp | G6: ログイン情報を入力する画面
B7: ポータル | C7: 画面 | D7: BSPSFRPK03 | E7: 新規会員登録入力 | F7: BSPSFRPK03.jsp | G7: 新規会員情報を入力する画面
B8: ポータル | C8: 画面 | D8: BSPSFRPK04 | E8: 新規会員登録確認 | F8: BSPSFRPK04.jsp | G8: 入力した新規会員情報を確認する画面
B9: ポータル | C9: 画面 | D9: BSPSFRPK05 | E9: 新規会員登録完了 | F9: BSPSFRPK05.jsp | G9: 新規会員登録完了を表示する画面
B10: ポータル | C10: 画面 | D10: BSPSFRPK06 | E10: パスワード再発行 | F10: BSPSFRPK06.jsp | G10: パスワードを再発行する画面
B11: ポータル | C11: 画面 | D11: BSPSFRPK07 | E11: パスワード再発行完了 | F11: BSPSFRPK07.jsp
B12: ポータル | C12: 画面 | D12: BSPSFRPK08 | E12: マイメニュー | F12: BSPSFRPK08.jsp | G12: ログインユーザー用TOPページ
B13: ポータル | C13: 画面 | D13: BSPSFRPK09 | E13: お知らせ・通知一覧 | F13: BSPSFRPK09.jsp | G13: 通知一覧
B14: ポータル | C14: 画面 | D14: BSPSFRPK10 | E14: お知らせ・通知詳細 | F14: BSPSFRPK10.jsp | G14: 通知詳細
B15: ポータル | C15: 画面 | D15: BSPSFRPK11 | E15: 対戦履歴 | F15: BSPSFRPK11.jsp | G15: 対戦履歴一覧
B16: ポータル | C16: 画面 | D16: BSPSFRPK12 | E16: 対戦履歴詳細 | F16: BSPSFRPK12.jsp | G16: 対戦履歴詳細
B17: ポータル | C17: 画面 | D17: BSPSFRPK13 | E17: マイデッキ | F17: BSPSFRPK13.jsp | G17: マイデッキ
B18: ポータル | C18: 画面 | D18: BSPSFRPK14 | E18: マイフレンド | F18: BSPSFRPK14.jsp | G18: フレンド一覧と各フレンドとのステータスを表示する画面
B19: ポータル | C19: 画面 | D19: BSPSFRPK15 | E19: チャット | F19: BSPSFRPK15.jsp | G19: 各フレンドとのメッセージを表示する画面
B20: ポータル | C20: 画面 | D20: BSPSFRPK16 | E20: フレンド追加 | F20: BSPSFRPK16.jsp | G20: 新規フレンド追加
B21: ポータル | C21: 画面 | D21: BSPSFRPK17 | E21: マイプロフィール | F21: BSPSFRPK17.jsp | G21: マイプロフィールを表示、編集する画面
B22: カードデッキ | C22: 画面 | D22: BSPSFRCD01 | E22: サイトTOP | F22: BSPSFRCD01.jsp | G22: サイトTOP、サイト初期表示時このページが呼ばれる
B23: カードデッキ | C23: 画面 | D23: BSPSFRCD02 | E23: カード一覧 | F23: BSPSFRCD02.jsp | G23: カード一覧
B24: カードデッキ | C24: 画面 | D24: BSPSFRCD03 | E24: カード詳細 | F24: BSPSFRCD03.jsp | G24: カード詳細

Sheet イベント一覧
B2: イベント一覧
B4: 画面間/画面内 | C4: イベントID | D4: イベント名 | E4: 呼び出し条件 | F4: ファイル名 | G4: 処理概要 | H4: 遷移先画面 | I4: 呼び出し処理名
B5: 画面間 | C5: BSPSFRPK01_BS01 | D5: 共通エリア初期表示 | E5: 本画面にリダイレクト遷移した時 | F5: BSPSFRPK01_BS01.servlet | G5: 「BSPSBCPK0101_共通エリア初期表示」を呼び出す。 | H5: - | I5: BSPSBCPK01_B01_共通エリア初期表示
B6: 画面間 | C6: BSPSFRPK01_BS02 | D6: サイトTOP遷移 | E6: サイトロゴ押下時 | G6: サイトTOP画面へリダイレクトする。 | H6: サイトTOP | I6: BSPSFRPK01_B02_サイトTOP遷移
B7: 画面間 | C7: BSPSFRPK01_BS03 | D7: ログイン遷移 | E7: ログインボタン押下時 | G7: ログイン画面へリダイレクトする。 | H7: ログイン | I7: BSPSFRPK01_B03_ログイン遷移
B8: 画面間 | C8: BSPSFRPK01_BS04 | D8: マイメニュー遷移 | E8: マイメニュー押下時 | G8: マイメニュー初期表示処理を呼び出す。 | H8: マイメニュー | I8: マイメニュー初期表示処理を呼び出す。
B9: 画面間 | C9: BSPSFRPK01_BS05 | D9: お知らせ遷移 | E9: お知らせ押下時 | G9: お知らせ初期表示処理を呼び出す | H9: お知らせ・通知一覧 | I9: お知らせ初期表示処理を呼び出す
B10: 画面間 | C10: BSPSFRPK01_BS06 | D10: マイデッキ遷移 | E10: マイデッキ押下時 | G10: マイデッキ画面へリダイレクトする。 | H10: マイデッキ | I10: マイデッキ画面へリダイレクトする。
B11: 画面間 | C11: BSPSFRPK01_BS07 | D11: 対戦履歴遷移 | E11: 対戦履歴押下時 | G11: 対戦履歴画面へリダイレクトする。 | H11: 対戦履歴一覧 | I11: 対戦履歴画面へリダイレクトする。
B12: 画面間 | C12: BSPSFRPK01_BS08 | D12: マイフレンド遷移 | E12: マイフレンド押下時 | G12: マイフレンド画面へリダイレクトする。 | H12: マイフレンド一覧 | I12: マイフレンド画面へリダイレクトする。
B13: 画面間 | C13: BSPSFRPK01_BS09 | D13: マイプロフィール遷移 | E13: マイプロフィール押下時 | G13: マイプロフィール画面へリダイレクトする。 | H13: マイプロフィール | I13: マイプロフィール画面へリダイレクトする。
B14: 画面間 | C14: BSPSFRPK01_BS10 | D14: ログアウト | E14: ログアウト押下時 | G14: 「BSPSBCPK0102_ログアウト処理」を呼び出す。 ※セッションをすべて破棄し、 ログイン画面へリダイレクトする。 | H14: ログアウト | I14: 「BSPSBCPK0102_ログアウト処理」を呼び出す。 ※セッションをすべて破棄し、 ログイン画面へリダイレクトする。
B15: 画面間 | C15: BSPSFRPK01_BS11 | D15: カード検索 | E15: カード検索押下時 | G15: 「BSPSFRPK0103_カード検索処理」を呼び出す。 ※セッションをすべて破棄し、 ログイン画面へリダイレクトする。 | H15: カード一覧 | I15: 「BSPSFRPK0103_カード検索処理」を呼び出す。 ※セッションをすべて破棄し、 ログイン画面へリダイレクトする。
B16: 画面内 | C16: BSPSFRPK01_IS01 | D16: ユーザーメニューを表示/非表示 | E16: ユーザー名押下時 | G16: ①ユーザー名ボタンを押下した時、以下項目を表示する。 1-4.対戦履歴 1-5.フレンド 1-6.プロフィール情報 1-7.ログアウト ②再度、ユーザー名を押下した時、上記項目を非表示にする。 | H16: - | I16: ①ユーザー名ボタンを押下した時、以下項目を表示する。 1-4.対戦履歴 1-5.フレンド 1-6.プロフィール情報 1-7.ログアウト ②再度、ユーザー名を押下した時、上記項目を非表示にする。

Sheet API一覧
B2: API処理一覧
B4: 業務分類 | C4: 機能分類 | D4: 機能ID | E4: 機能名 | F4: ファイル名 | G4: 備考
B5: ポータル | C5: API | D5: BSPSAPPK01 | E5: ユーザー取得API | G5: ユーザー情報をDBから取得するAPI
B6: カードデッキ | C6: API | D6: BSPSAPCD01 | E6: カード検索用リスト取得API | G6: カード検索用のプルダウンのリストを取得するAPI

Sheet 元データ
B2: 画面・処理・API紐づけ資料
B4: 業務分類 | C4: 画面ID | D4: 画面名 | E4: 画面間/画面内 | F4: イベントID | G4: イベント名 | H4: 遷移先画面 | I4: APIID | J4: API名称
B5: ポータル | C5: BSPSFRPK01 | D5: 共通エリア | E5: 画面間 | F5: BSPSFRPK01_BS01 | G5: 共通エリア初期表示 | H5: - | I5: BSPSAPPK01 | J5: ユーザー取得API
B6: ポータル | C6: BSPSFRPK01 | D6: 共通エリア | E6: 画面間 | F6: BSPSFRPK01_BS01 | G6: 共通エリア初期表示 | H6: - | I6: BSPSAPCD01 | J6: カード検索用リスト取得API
B7: ポータル | C7: BSPSFRPK01 | D7: 共通エリア | E7: 画面間 | F7: BSPSFRPK01_BS02 | G7: サイトTOP遷移 | H7: サイトTOP | I7: - | J7: -
B8: ポータル | C8: BSPSFRPK01 | D8: 共通エリア | E8: 画面間 | F8: BSPSFRPK01_BS03 | G8: ログイン遷移 | H8: ログイン | I8: - | J8: -
B9: ポータル | C9: BSPSFRPK01 | D9: 共通エリア | E9: 画面間 | F9: BSPSFRPK01_BS04 | G9: マイメニュー遷移 | H9: マイメニュー | I9: - | J9: -
B10: ポータル | C10: BSPSFRPK01 | D10: 共通エリア | E10: 画面間 | F10: BSPSFRPK01_BS05 | G10: お知らせ遷移 | H10: お知らせ・通知一覧 | I10: - | J10: -
B11: ポータル | C11: BSPSFRPK01 | D11: 共通エリア | E11: 画面間 | F11: BSPSFRPK01_BS06 | G11: マイデッキ遷移 | H11: マイデッキ | I11: - | J11: -
B12: ポータル | C12: BSPSFRPK01 | D12: 共通エリア | E12: 画面間 | F12: BSPSFRPK01_BS07 | G12: 対戦履歴遷移 | H12: 対戦履歴一覧 | I12: - | J12: -
B13: ポータル | C13: BSPSFRPK01 | D13: 共通エリア | E13: 画面間 | F13: BSPSFRPK01_BS08 | G13: マイフレンド遷移 | H13: マイフレンド一覧 | I13: - | J13: -
B14: ポータル | C14: BSPSFRPK01 | D14: 共通エリア | E14: 画面間 | F14: BSPSFRPK01_BS09 | G14: マイプロフィール遷移 | H14: マイプロフィール | I14: - | J14: -
B15: ポータル | C15: BSPSFRPK01 | D15: 共通エリア | E15: 画面間 | F15: BSPSFRPK01_BS10 | G15: ログアウト | H15: ログアウト | I15: - | J15: -
... B17: ポータル | C17: BSPSFRPK01 | D17: 共通エリア | E17: 画面内 | F17: BSPSFRPK01_IS01 | G17: ユーザーメニューを表示/非表示 | H17: - | I17: - | J17: -
B18: ポータル | C18: BSPSFRPK02 | D18: ログイン
B19: ポータル | C19: BSPSFRPK03 | D19: 新規会員登録入力
B20: ポータル | C20: BSPSFRPK04 | D20: 新規会員登録確認
B21: ポータル | C21: BSPSFRPK05 | D21: 新規会員登録完了
B22: ポータル | C22: BSPSFRPK06 | D22: パスワード再発行
B23: ポータル | C23: BSPSFRPK07 | D23: パスワード再発行完了
B24: ポータル | C24: BSPSFRPK08 | D24: マイメニュー
B25: ポータル | C25: BSPSFRPK09 | D25: お知らせ・通知一覧
B26: ポータル | C26: BSPSFRPK10 | D26: お知らせ・通知詳細
B27: ポータル | C27: BSPSFRPK11 | D27: 対戦履歴
B28: ポータル | C28: BSPSFRPK12 | D28: 対戦履歴詳細
B29: ポータル | C29: BSPSFRPK13 | D29: マイデッキ
... B36: カードデッキ | C36: BSPSFRCD03 | D36: カード詳細

Sheet 画面・イベント・API紐づけ資料
A1: 画面・イベント・API紐づけ資料
A3: 画面ID | B3: 機能ID | C3: 画面名 | D3: イベントID | E3: イベント名 | F3: 呼び出しAPI | G3: APIID
A4: カードデッキ | B4: BSPSFRCD01 | C4: サイトTOP | D4: (空白) | E4: (空白) | F4: (空白) | G4: (空白)
B5: BSPSFRCD02 | C5: カード一覧 | D5: (空白) | E5: (空白) | F5: (空白) | G5: (空白)
B6: BSPSFRCD03 | C6: カード詳細 | D6: (空白) | E6: (空白) | F6: (空白) | G6: (空白)
A7: ポータル | B7: BSPSFRPK01 | C7: 共通エリア | D7: BSPSFRPK01_BS01 | E7: 共通エリア初期表示 | F7: カード検索用リスト取得API | G7: BSPSAPCD01
F8: ユーザー取得API | G8: BSPSAPPK01
D9: BSPSFRPK01_BS02 | E9: サイトTOP遷移 | F9: - | G9: -
D10: BSPSFRPK01_BS03 | E10: ログイン遷移 | F10: - | G10: -
D11: BSPSFRPK01_BS04 | E11: マイメニュー遷移 | F11: - | G11: -
D12: BSPSFRPK01_BS05 | E12: お知らせ遷移 | F12: - | G12: -
D13: BSPSFRPK01_BS06 | E13: マイデッキ遷移 | F13: - | G13: -
D14: BSPSFRPK01_BS07 | E14: 対戦履歴遷移 | F14: - | G14: -
D15: BSPSFRPK01_BS08 | E15: マイフレンド遷移 | F15: - | G15: -
D16: BSPSFRPK01_BS09 | E16: マイプロフィール遷移 | F16: - | G16: -
D17: BSPSFRPK01_BS10 | E17: ログアウト | F17: - | G17: -
D18: BSPSFRPK01_BS11 | E18: カード検索 | F18: - | G18: -
D19: BSPSFRPK01_IS01 | E19: ユーザーメニューを表示/非表示 | F19: - | G19: -
B20: BSPSFRPK02 | C20: ログイン | D20: (空白) | E20: (空白) | F20: (空白) | G20: (空白)
B21: BSPSFRPK03 | C21: 新規会員登録入力 | D21: (空白) | E21: (空白) | F21: (空白) | G21: (空白)
B22: BSPSFRPK04 | C22: 新規会員登録確認 | D22: (空白) | E22: (空白) | F22: (空白) | G22: (空白)
B23: BSPSFRPK05 | C23: 新規会員登録完了 | D23: (空白) | E23: (空白) | F23: (空白) | G23: (空白)
B24: BSPSFRPK06 | C24: パスワード再発行 | D24: (空白) | E24: (空白) | F24: (空白) | G24: (空白)
B25: BSPSFRPK07 | C25: パスワード再発行完了 | D25: (空白) | E25: (空白) | F25: (空白) | G25: (空白)
B26: BSPSFRPK08 | C26: マイメニュー | D26: (空白) | E26: (空白) | F26: (空白) | G26: (空白)
B27: BSPSFRPK09 | C27: お知らせ・通知一覧 | D27: (空白) | E27: (空白) | F27: (空白) | G27: (空白)
B28: BSPSFRPK10 | C28: お知らせ・通知詳細 | D28: (空白) | E28: (空白) | F28: (空白) | G28: (空白)
B29: BSPSFRPK11 | C29: 対戦履歴 | D29: (空白) | E29: (空白) | F29: (空白) | G29: (空白)
B30: BSPSFRPK12 | C30: 対戦履歴詳細 | D30: (空白) | E30: (空白) | F30: (空白) | G30: (空白)
B31: BSPSFRPK13 | C31: マイデッキ | D31: (空白) | E31: (空白) | F31: (空白) | G31: (空白)
... B35: BSPSFRPK17 | C35: マイプロフィール | D35: (空白) | E35: (空白) | F35: (空白) | G35: (空白)
A36: 総計

Sheet API呼び出し画面
A1: API呼び出し画面
C3: 列ラベル
C4: お知らせ・通知一覧 | D4: お知らせ・通知一覧 集計 | E4: お知らせ・通知詳細 | F4: お知らせ・通知詳細 集計 | G4: カード一覧 | H4: カード一覧 集計 | I4: カード詳細 | J4: カード詳細 集計 | K4: サイトTOP | L4: サイトTOP 集計 | M4: チャット | N4: チャット 集計 | O4: パスワード再発行 | P4: パスワード再発行 集計 | Q4: パスワード再発行完了 | R4: パスワード再発行完了 集計 | S4: フレンド追加 | T4: フレンド追加 集計 | U4: マイデッキ | V4: マイデッキ 集計 | W4: マイフレンド | X4: マイフレンド 集計 | Y4: マイプロフィール | Z4: マイプロフィール 集計 | AA4: マイメニュー | AB4: マイメニュー 集計 | AC4: ログイン | AD4: ログイン 集計 | AE4: 共通エリア | AF4: 共通エリア 集計 | AG4: 新規会員登録確認 | AH4: 新規会員登録確認 集計 | AI4: 新規会員登録完了 | AJ4: 新規会員登録完了 集計 | AK4: 新規会員登録入力 | AL4: 新規会員登録入力 集計 | AM4: 対戦履歴 | AN4: 対戦履歴 集計 | AO4: 対戦履歴詳細 | AP4: 対戦履歴詳細 集計 | AQ4: 総計
A5: 行ラベル | B5: 呼び出しAPI | C5: BSPSFRPK09 | E5: BSPSFRPK10 | G5: BSPSFRCD02 | I5: BSPSFRCD03 | K5: BSPSFRCD01 | M5: BSPSFRPK15 | O5: BSPSFRPK06 | Q5: BSPSFRPK07 | S5: BSPSFRPK16 | U5: BSPSFRPK13 | W5: BSPSFRPK14 | Y5: BSPSFRPK17 | AA5: BSPSFRPK08 | AC5: BSPSFRPK02 | AE5: BSPSFRPK01 | AG5: BSPSFRPK04 | AI5: BSPSFRPK05 | AK5: BSPSFRPK03 | AM5: BSPSFRPK11 | AO5: BSPSFRPK12
A6: - | B6: -
A7: BSPSAPCD01 | B7: カード検索用リスト取得API
A8: BSPSAPPK01 | B8: ユーザー取得API
A9: (空白) | B9: (空白)
A10: 総計

Sheet 画面遷移図
B2: システムID | H2: =表紙!H5 -> BSPS | M2: システム名 | T2: =表紙!T5 -> バトルシミレーションポータルサイト | AS2: 版数 | AV2: =表紙!N14 -> 1.4
B3: サブシステムID | H3: =表紙!H6 -> - | M3: サブシステム名 | T3: =表紙!T6 -> - | AJ3: 作成者 | AM3: =表紙!N10 -> 須賀 | AS3: 更新者 | AV3: =表紙!N12 -> 須賀
B4: 機能ID | H4: =表紙!H7 -> - | M4: 機能名 | T4: =表紙!T7 -> - | AJ4: 作成日 | AM4: =表紙!N11 -> 44464 | AS4: 更新者 | AV4: =表紙!N13 -> 44520
B6: 画面フロー_ポータル機能
B8: 画面フロー
B9: ◆ポータル_アカウント系
C11: BSPSFRPK01_共通エリア
U12: BSPSFRPK03_新規会員登録 | AD12: BSPSFRPPK04_新規会員登確認 | AO12: BSPSFRPPK05_新規会員登完了
C13: 新規会員登録
L15: BSPSFRPK02_ログイン | U15: 入力内容を確認 | AD15: 上記の内容で登録 | AO15: ログインする
C17: ログイン | L17: 新規登録はこちら
C18: ログアウト
U19: 戻る | AD19: 戻る
U24: BSPSFRPK06_パスワード再発行 | AF24: BSPSFRPK07_パスワード再発行完了
L25: パスワードを忘れた方はこちら
U26: パスワードを再発行する
U28: 戻る | AF28: ログインする
B34: ◆ポータル_マイメニュー
U35: BSPSFRPK08_マイメニュー
L36: ログイン
C38: マイメニュー | AF38: BSPSFRPK09_お知らせ・通知一覧 | AR38: BSPSFRPK10_お知らせ・通知詳細
C40: お知らせ
U42: お知らせ・通知を確認する | AF42: 該当通知を選択
AF44: マイメニューへ戻る | AQ44: お知らせ・通知一覧へ戻る
AF47: BSPSFRPK11_対戦履歴一覧 | AQ47: BSPSFRPK12_対戦履歴詳細
C48: 対戦履歴
U50: 対戦履歴を確認する | AF50: 該当履歴を選択
AF53: マイメニューへ戻る | AQ53: 対戦履歴一覧へ戻る
AF56: BSPSFRPK13_マイデッキ
C57: マイデッキ
U59: マイデッキを確認する | AF59: 該当デッキを選択 | AQ59: ※デッキ詳細
AF61: マイメニューへ戻る
AF65: BSPSFRPK14_マイフレンド | AQ65: BSPSFRPK15_チャット
C66: マイフレンド
U68: マイフレンドを確認する | AF68: 該当フレンドを選択 | AQ68: 該当フレンドを選択 | AY68: ※チャット画面にリダイレクト
AQ70: マイフレンドへ戻る
AQ73: BSPSFRPK16_フレンド追加
AF75: フレンドを追加する | AQ75: 該当フレンドを選択
AF77: マイメニューへ戻る | AQ77: マイフレンドへ戻る
AF80: BSPSFRPK17_マイプロフィール
...
