Workbook

Sheet 変更履歴
A1: No | B1: 変更対象シート | C1: 変更内容 | D1: 更新者 | E1: 更新日
A2: =ROW()-1 -> 1 | C2: 新規 | D2: LKG | E2: 2021/2/18
A3: =ROW()-1 -> 2
A4: =ROW()-1 -> 3
A5: =ROW()-1 -> 4
A6: =ROW()-1 -> 5
A7: =ROW()-1 -> 6
A8: =ROW()-1 -> 7
A9: =ROW()-1 -> 8
A10: =ROW()-1 -> 9
A11: =ROW()-1 -> 10
A12: =ROW()-1 -> 11
A13: =ROW()-1 -> 12
A14: =ROW()-1 -> 13
... A21: =ROW()-1 -> 20

Sheet DocuSign認証
A1: 処理設計 | G1: サブシステム名 | M1: BSP-対戦共通 | V1: 処理名 | AB1: シャッフル | BH1: 作成日 | BM1: 2021/8/19 | BS1: 更新日
G2: サブシステムID | M2: - | BH2: 作成者 | BM2: =変更履歴!D2 -> LKG | BS2: 更新者
A4: パッケージ名 | G4: jp.co.kuronekoyamato.commonapi.web.service | AP4: 処理概要
A5: クラス名 | G5: BattleUtil | V5: メソッド名 | AB5: shuffleDeck
A6: 引数 | AQ6: 【使用目的】
A7: No | C7: 入／入出 | G7: 論理名 | O7: 物理名 | W7: 型 | AC7: 説明 | AS7: DocuSign認証、アカウントIDを取得。
A8: 1 | C8: 入力 | G8: デッキinfo | O8: deckInfo | W8: List<CardObject>
A9: 2 | C9: 入力 | G9: カード情報 | P9: cardInfo | W9: String | X9: CardObject | AQ9: 【エラー条件】
A10: 3 | C10: 入力 | G10: カードID | Q10: integratorKey | W10: String | AS10: 特になし
A11: 4 | C11: 入力 | G11: 位置情報 | Q11: privateKeyBytes | W11: String
AQ14: 【処理仕様】
AS15: ①開発、ステージ、本番により、OAuth JWT構築ライセンスuriを取得する。
AS16: ②DockSignからの新しいOAuth JWTを使用してトークン構成AiClientにアクセスする現在の例、oAuthTokenをを取得
AS17: ③oAuthTokenでユーザ情報を取得します。
A18: 戻り値 | AS18: ④ | AT18: ユザ情報からアカウントIDを取得する。
A19: No | C19: 論理名 | K19: 物理名 | S19: 型 | X19: 説明
A20: 1 | C20: アカウントID | K20: accountId | S20: String
A21: 2
A22: 3
A23: 4 | AQ23: 【注意事項】
A24: 5 | AS24: 呼び出し例
A25: ＣＲＵＤ
A26: No | C26: 種別 | G26: C | H26: R | I26: U | J26: D | K26: 名称 | AD26: ID | AF26: 備考 | AT26: String accountId = this.getAuthentication();
A27: 1 | AT27: ※入力内容はappication.properties設定
A28: 2
A29: 3 | AS29: application.properties
A30: 4 | AT30: clientId | AW30: DocuSignのシステムのKeｙ、環境構築次第
A31: 5 | AT31: userId | AW31: DocuSignのユーザID、環境構築次第
A32: 6 | AT32: scopes | AW32: アクセスのスコープ、"signature"として固定する
A33: 7 | AT33: privateKeyBytes | AZ33: DocuSignのプロジェクトの RSA private key、環境構築次第
A34: 8 | AT34: expiresIn | AY34: Tokenの有効期限、3600秒に設定する
A35: 9 | AT35: BaseUrl | AX35: https://account-d.docusign.com 開発環境
A36: 10 | AX36: https://account.docusign.com 本番環境

Sheet DocuSignエンベロープ作成
A1: 処理設計 | G1: サブシステム名 | M1: アプリ共通 | V1: 処理名 | AB1: エンベロープ作成 | BH1: 作成日 | BM1: =変更履歴!E2 -> 2021/2/18 | BS1: 更新日
G2: サブシステムID | M2: - | BH2: 作成者 | BM2: =変更履歴!D2 -> LKG | BS2: 更新者
A4: パッケージ名 | G4: jp.co.kuronekoyamato.commonapi.web.service | AP4: 処理概要
A5: クラス名 | G5: SignService | V5: メソッド名 | AB5: uploadSignatureFile
A6: 引数 | AQ6: 【使用目的】
A7: No | C7: 入／入出 | G7: 論理名 | O7: 物理名 | W7: 型 | AC7: 説明 | AS7: 契約書をアップして、エンベロープをPOST送信、DocuSignエンベロープ作成して、エンベロープIDを取得
A8: 1 | C8: 入力 | G8: ファイルのストリーム | O8: fileBytes | W8: byte[] | AC8: 署名ファイルの中身
A9: 2 | C9: 入力 | G9: 署名ユーザーLIST | O9: signList | W9: List<SignRequestData> | AQ9: 【エラー条件】
A10: 3 | G10: ユーザーID | P10: clientUserId | X10: String | AC10: ユーザーID | AS10: 「ユーザー名」と「メール」が重複する場合：httpStatus:500
A11: 4 | G11: ユーザー名 | P11: name | X11: String | AC11: ユーザー名 | AS11: 「ファイルのストリーム」がNULLの場合：httpStatus:500
A12: 5 | G12: メール | P12: email | X12: String | AC12: メール | AS12: 「メール」が正しいフォーマットではない場合：httpStatus:500
A13: 6 | G13: ファイル署名ページ | P13: pageNumber | X13: String | AC13: ファイル署名ページ
A14: 7 | G14: 署名のXロケーション | P14: signXPosition | X14: String | AC14: 署名のXロケーション
A15: 8 | G15: 署名のYロケーション | P15: signYPosition | X15: String | AC15: 署名のYロケーション
A16: 9 | G16: 署名の太さ | P16: signScaleValue | X16: String | AC16: 署名の太さ | AQ16: 【処理仕様】
A17: 10 | G17: 日付のXロケーション | P17: dateXPosition | X17: String | AC17: 日付のXロケーション | AT17: ①エンベロープ定義作成。
A18: 11 | G18: 日付のYロケーション | P18: dateYPosition | X18: String | AC18: 日付のYロケーション | AT18: ②書類をエンベロープに加える。
A19: 12 | G19: 日付のフォントのサイズ | P19: dateFontSize | X19: String | AC19: 日付のフォントのサイズ | AT19: ③受信者の署名情報をループする。
A20: 13 | G20: 全名称のXロケーション | P20: fullNameXPosition | X20: String | AC20: 全名称のXロケーション | AT20: ④文書のどこかにSignHereタブを作成し、署名者情報を追加する。
A21: 14 | G21: 全名称のYロケーション | P21: fullNameYPosition | X21: String | AC21: 全名称のYロケーション | AT21: ⑤認証処理を実施して、アカウントIDを取得する。
A22: 15 | G22: 全名称のフォントのサイズ | P22: fullNameFontSize | X22: String | AC22: 全名称のフォントのサイズ | AT22: ⑥エンベロープ作成APIを呼び出す、エンベロープを取得する。
A23: 16 | C23: 入力 | G23: ファイル名 | O23: fileName | W23: String | AC23: ファイル名 | AU23: ※日付のXロケーションと日付のYロケーションがないの場合、署名画面に日付を表示しない。
A24: 17 | C24: 入力 | G24: 署名宣伝文 | O24: blurb | W24: String | AC24: 署名宣伝文 | AU24: ※全名称のXロケーションと全名称のYロケーションがないの場合、署名画面に全名称を表示しない。
A25: 戻り値 | AT25: ⑦エンベロープからのエンベロープIDを返す。
A26: No | C26: 論理名 | K26: 物理名 | S26: 型 | X26: 説明
A27: 1 | C27: エンベロープID | K27: envelopeId | S27: String
A28: 2 | AQ28: 【注意事項】
A29: 3 | AR29: ※clientUserIdは同じ値を指定するはエラーにならないが、禁止です。
A30: 4 | AR30: 呼び出し例
A31: 5 | AR31: String envelopeId =
A32: ＣＲＵＤ | AR32: signService.uploadSignatureFile(Paths.get(filePath), signList, fileName.split("\\.")[0]+"_"+format.format(date)+"."+fileName.split("\\.")[1]);
A33: No | C33: 種別 | G33: C | H33: R | I33: U | J33: D | K33: 名称 | AD33: ID | AF33: 備考
A34: 1 | C34: テーブル | H34: ● | K34: 署名定義テーブル | AF34: テーブル作成中 | AQ34: ※事前に署名テンプレートを準備するのはこの部品を利用できません。
A35: 2 | C35: テーブル | G35: ● | K35: エンベロープ情報テーブル | AF35: テーブル作成中 | AQ35: ※署名ファイルに署名個所：ファイルID、ページID、届くID、ポジションX,ポジションY,署名文字スケール は事前にDBに保管しておく
A36: 3
A37: 4 | AQ37: ※作成したエンベロープ情報をテーブルに登録する時、失敗した場合、DocuSginのサーバの情報
A38: 5 | AQ38: とエンベロープ情報テーブルが一致しないため、全体を作成失敗とする、envelopeIdもNULLにする。
A39: 6
A40: 7
A41: 8
...

Sheet DocuSign署名画面のURLを取得
A1: 処理設計 | G1: サブシステム名 | M1: アプリ共通 | V1: 処理名 | AB1: 署名画面のURLを取得 | BH1: 作成日 | BM1: =変更履歴!E2 -> 2021/2/18 | BS1: 更新日
G2: サブシステムID | M2: - | BH2: 作成者 | BM2: =変更履歴!D2 -> LKG | BS2: 更新者
A4: パッケージ名 | G4: jp.co.kuronekoyamato.commonapi.web.service | AP4: 処理概要
A5: クラス名 | G5: SignService | V5: メソッド名 | AB5: embeddedSigningByEnvelopeId
A6: 引数 | AQ6: 【使用目的】
A7: No | C7: 入／入出 | G7: 論理名 | O7: 物理名 | W7: 型 | AC7: 説明 | AS7: ユーザー情報によって署名表示URLに戻ります。
A8: 1 | C8: 入力 | G8: エンペローブID | O8: envelopeId | W8: String | AC8: エンベロープ作成した時の戻り値
A9: 2 | C9: 入力 | G9: ユーザーID | O9: clientUserId | W9: String | AC9: エンベロープ作成と同じの引数 | AQ9: 【エラー条件】
A10: 3 | C10: 入力 | G10: ユーザー名 | O10: name | W10: String | AC10: エンベロープ作成と同じの引数 | AS10: 特になし
A11: 4 | C11: 入力 | G11: メール | O11: email | W11: String | AC11: エンベロープ作成と同じの引数
A12: 5 | C12: 入力 | G12: 次のURL | O12: returnUrl | W12: String | AC12: 署名画面の完了ボタンクリックした後
AQ14: 【処理仕様】
AT15: ①認証処理を実施して、アカウントIDを取得する。
AT16: ②POST送信、署名表示URLに戻ります。
A18: 戻り値
A19: No | C19: 論理名 | K19: 物理名 | S19: 型 | X19: 説明 | AQ19: 【注意事項】
A20: 1 | C20: 表示URL | K20: viewUrl | S20: String | AS20: 呼び出し例
A21: 2
A22: 3 | AT22: String viewUrl =
A23: 4 | AT23: signService.embeddedSigningByEnvelopeId(envelopeId, clientUserId, name, email);
A24: 5
A25: ＣＲＵＤ
A26: No | C26: 種別 | G26: C | H26: R | I26: U | J26: D | K26: 名称 | AD26: ID | AF26: 備考 | AS26: 表示URLはクライアント側で署名する画面に利用する。
A27: 1 | AS27: 次のURLは署名画面の完了ボタンクリックした後の遷移先です。
A28: 2
A29: 3
A30: 4
A31: 5
A32: 6
A33: 7
A34: 8
A35: 9

Sheet DocuSignエンベロープのステータス取得
A1: 処理設計 | G1: サブシステム名 | M1: アプリ共通 | V1: 処理名 | AB1: エンベロープステータス取得 | BH1: 作成日 | BM1: =変更履歴!E2 -> 2021/2/18 | BS1: 更新日
G2: サブシステムID | M2: - | BH2: 作成者 | BM2: =変更履歴!D2 -> LKG | BS2: 更新者
A4: パッケージ名 | G4: jp.co.kuronekoyamato.commonapi.web.service | AP4: 処理概要
A5: クラス名 | G5: SignService | V5: メソッド名 | AB5: getStatusByEnvelopeId
A6: 引数 | AQ6: 【使用目的】
A7: No | C7: 入／入出 | G7: 論理名 | O7: 物理名 | W7: 型 | AC7: 説明 | AS7: エンベロープ情報によってDocuSignエンベロープのステータス取得。
A8: 1 | C8: 入力 | G8: エンペローブID | O8: envelopeId | W8: String | AC8: エンベロープ作成した時の戻り値
AQ9: 【エラー条件】
AS10: 特になし
AQ14: 【処理仕様】
AT15: ①認証処理を実施して、アカウントIDを取得する。
AT16: ②指定したエンベロープのステータスを取得する。
A18: 戻り値
A19: No | C19: 論理名 | K19: 物理名 | S19: 型 | X19: 説明 | AQ19: 【注意事項】
A20: 1 | C20: エンベロープのステータス | K20: envelopeStatus | S20: String | X20: エンベロープのステータス | AS20: 呼び出し例
A21: 2
A22: 3 | AT22: String status =
A23: 4 | AT23: signService.getStatusByEnvelopeId(envelopeId);
A24: 5
A25: ＣＲＵＤ
A26: No | C26: 種別 | G26: C | H26: R | I26: U | J26: D | K26: 名称 | AD26: ID | AF26: 備考
A27: 1 | C27: テーブル | I27: ● | K27: エンベロープ情報テーブル | AF27: 論理的削除 | AT27: ステータス
A28: 2 | AT28: ※sent:作成済み
A29: 3 | AT29: ※completed:署名済み
A30: 4 | AT30: ※viod:取り下げ済み
A31: 5 | AT31: ※declined:辞退
A32: 6
A33: 7
A34: 8
A35: 9

Sheet DocuSignエンベロープを取り下げ
A1: 処理設計 | G1: サブシステム名 | M1: アプリ共通 | V1: 処理名 | AB1: エンベロープを取り下げ | BH1: 作成日 | BM1: =変更履歴!E2 -> 2021/2/18 | BS1: 更新日
G2: サブシステムID | M2: - | BH2: 作成者 | BM2: =変更履歴!D2 -> LKG | BS2: 更新者
A4: パッケージ名 | G4: jp.co.kuronekoyamato.commonapi.web.service | AP4: 処理概要
A5: クラス名 | G5: SignService | V5: メソッド名 | AB5: viodEnvelope
A6: 引数 | AQ6: 【使用目的】
A7: No | C7: 入／入出 | G7: 論理名 | O7: 物理名 | W7: 型 | AC7: 説明 | AS7: エンベロープ情報によってエンベロープを取り下げ。
A8: 1 | C8: 入力 | G8: エンペローブID | O8: envelopeId | W8: String | AC8: エンベロープ作成した時の戻り値
A9: 2 | C9: 入力 | G9: 取り下げ理由 | O9: voidedReason | W9: String | AQ9: 【エラー条件】
AS10: ステータスが下記の署名済みの場合、取り下げ処理ができないです。
AQ14: 【処理仕様】
AT15: ①認証処理を実施して、アカウントIDを取得する。
AT16: ②指定しているエンペローブIDと取り下げ理由により、エンペローブを廃棄する。
A18: 戻り値
A19: No | C19: 論理名 | K19: 物理名 | S19: 型 | X19: 説明 | AQ19: 【注意事項】
A20: 1 | C20: 処理エラーの結果 | K20: errorDetails | S20: ErrorDetails | X20: 処理エラーの場合、戻るメッセージ | AS20: 呼び出し例
A21: 2 | T21: errorCode | AT21: String voidedReason = "契約を取り下げる"；
A22: 3 | T22: message | AT22: String errorDetails =
A23: 4 | AT23: signService.viodEnvelope(envelopeId,voidedReason);
A24: 5
A25: ＣＲＵＤ
A26: No | C26: 種別 | G26: C | H26: R | I26: U | J26: D | K26: 名称 | AD26: ID | AF26: 備考
A27: 1 | C27: テーブル | I27: ● | K27: エンベロープ情報テーブル | AF27: 論理的削除 | AT27: ステータスが下記の署名済みの場合、取り下げ処理ができないです。
A28: 2 | AT28: ※completed:署名済み
A29: 3 | AT29: errorDetailsがないの場合、問題なく取り下げ処理ができました。その以外の場合、エラーメッセージerrorDetailsを戻す。
A30: 4
A31: 5
A32: 6
A33: 7
A34: 8
A35: 9

Sheet DocuSignエンベロープのユーザ署名ステータス取得(1)
A1: 処理設計 | G1: サブシステム名 | M1: アプリ共通 | V1: 処理名 | AB1: DocuSignエンベロープのユーザ署名ステータス取得 | BH1: 作成日 | BM1: =変更履歴!E2 -> 2021/2/18 | BS1: 更新日
G2: サブシステムID | M2: - | BH2: 作成者 | BM2: =変更履歴!D2 -> LKG | BS2: 更新者
A4: パッケージ名 | G4: jp.co.kuronekoyamato.commonapi.web.service | AP4: 処理概要
A5: クラス名 | G5: SignService | V5: メソッド名 | AB5: getUserSignStatusByMail
A6: 引数 | AQ6: 【使用目的】
A7: No | C7: 入／入出 | G7: 論理名 | O7: 物理名 | W7: 型 | AC7: 説明 | AS7: エンベロープ情報によってユーザ署名ステータスを取得する。
A8: 1 | C8: 入力 | G8: エンペローブID | O8: envelopeId | W8: String | AC8: エンベロープ作成の戻り値
A9: 2 | C9: 入力 | G9: メールアドレス | O9: mail | W9: String | AC9: エンベロープ作成時のメールアドレス | AQ9: 【エラー条件】
AS10: 特になし
AQ14: 【処理仕様】
AT15: ①認証処理を実施して、アカウントIDを取得する。
AT16: ②POST送信、ユーザ署名ステータスを取得する。
AT17: ③署名した結果をエンベロープ署名情報テーブルに反映する。
A18: 戻り値
A19: No | C19: 論理名 | K19: 物理名 | S19: 型 | X19: 説明 | AQ19: 【注意事項】
A20: 1 | C20: ユーザ署名ステータス | K20: userStatus | S20: String | X20: エンベロープのステータス | AS20: 呼び出し例
A21: 2
A22: 3 | AT22: String status =
A23: 4 | AT23: signService.getUserSignStatus(envelopeId,mail);
A24: 5
A25: ＣＲＵＤ
A26: No | C26: 種別 | G26: C | H26: R | I26: U | J26: D | K26: 名称 | AD26: ID | AF26: 備考
A27: 1 | C27: テーブル | I27: ● | K27: エンベロープ署名情報テーブル | AT27: ステータス
A28: 2 | AT28: ※sent:作成済み
A29: 3 | AT29: ※completed:署名済み
A30: 4
A31: 5
A32: 6
A33: 7
A34: 8
A35: 9

Sheet DocuSignエンベロープのユーザ署名ステータス取得(2)
A1: 処理設計 | G1: サブシステム名 | M1: アプリ共通 | V1: 処理名 | AB1: DocuSignエンベロープのユーザ署名ステータス取得 | BH1: 作成日 | BM1: =変更履歴!E2 -> 2021/2/18 | BS1: 更新日
G2: サブシステムID | M2: - | BH2: 作成者 | BM2: =変更履歴!D2 -> LKG | BS2: 更新者
A4: パッケージ名 | G4: jp.co.kuronekoyamato.commonapi.web.service | AP4: 処理概要
A5: クラス名 | G5: SignService | V5: メソッド名 | AB5: getUserSignStatusByClientUserId
A6: 引数 | AQ6: 【使用目的】
A7: No | C7: 入／入出 | G7: 論理名 | O7: 物理名 | W7: 型 | AC7: 説明 | AS7: エンベロープ情報によってユーザ署名ステータスを取得する。
A8: 1 | C8: 入力 | G8: エンペローブID | O8: envelopeId | W8: String | AC8: エンベロープ作成の戻り値
A9: 2 | C9: 入力 | G9: 署名ユーザID | O9: clientUserId | W9: String | AC9: エンペローブの既存の署名者のメール | AQ9: 【エラー条件】
AS10: 特になし
AQ14: 【処理仕様】
AT15: ①認証処理を実施して、アカウントIDを取得する。
AT16: ②POST送信、ユーザ署名ステータスを取得する。
AT17: ③署名した結果をエンベロープ署名情報テーブルに反映する。
A18: 戻り値
A19: No | C19: 論理名 | K19: 物理名 | S19: 型 | X19: 説明 | AQ19: 【注意事項】
A20: 1 | C20: ユーザ署名ステータス | K20: userStatus | S20: String | X20: エンベロープのステータス | AS20: 呼び出し例
A21: 2
A22: 3 | AT22: String status =
A23: 4 | AT23: signService.getUserSignStatus(envelopeId,clientUserId );
A24: 5
A25: ＣＲＵＤ
A26: No | C26: 種別 | G26: C | H26: R | I26: U | J26: D | K26: 名称 | AD26: ID | AF26: 備考
A27: 1 | C27: テーブル | I27: ● | K27: エンベロープ署名情報テーブル | AT27: ステータス
A28: 2 | AT28: ※sent:作成済み
A29: 3 | AT29: ※completed:署名済み
A30: 4
A31: 5
A32: 6
A33: 7
A34: 8
A35: 9

Sheet 署名再依頼
A1: 処理設計 | G1: サブシステム名 | M1: アプリ共通 | V1: 処理名 | AB1: エンベロープ作成 | BH1: 作成日 | BM1: =変更履歴!E2 -> 2021/2/18 | BS1: 更新日
G2: サブシステムID | M2: - | BH2: 作成者 | BM2: =変更履歴!D2 -> LKG | BS2: 更新者
A4: パッケージ名 | G4: jp.co.kuronekoyamato.commonapi.web.service | AP4: 処理概要
A5: クラス名 | G5: SignService | V5: メソッド名 | AB5: replaceEnvelopeRecipient
A6: 引数 | AQ6: 【使用目的】
A7: No | C7: 入／入出 | G7: 論理名 | O7: 物理名 | W7: 型 | AC7: 説明 | AS7: 指定されたエンペローブの署名依頼先のメールと署名者名称を更新する。
A8: 1 | C8: 入力 | G8: エンペローブID | O8: envelopeId | W8: String | AC8: エンベロープ作成の戻り値
A9: 2 | C9: 入力 | G9: メール | O9: email | W9: String | AC9: エンベロープ作成した時の署名者メール | AQ9: 【エラー条件】
A10: 3 | C10: 入力 | G10: 新ユーザ名 | O10: newName | W10: String | AC10: 署名再依頼で指定する署名者名前 | AS10: 「ユーザー名」と「メール」が重複する場合：httpStatus:500
A11: 4 | C11: 入力 | G11: 新メール | O11: newEmail | W11: String | AC11: 署名再依頼で指定する署名者メール | AS11: 「ファイルのストリーム」がNULLの場合：httpStatus:500
A12: 5 | AS12: 「メール」が正しいフォーマットではない場合：httpStatus:500
A13: 6
A14: 7
A15: 8
A16: 9 | AQ16: 【処理仕様】
A17: 10 | AT17: ①指定したエンペローブIDにより、エンベロープのステータスを取得する。
A18: 11 | AT18: ②既に署名済みの場合、署名再依頼できないため、エラーをもどる。
A19: 戻り値 | AT19: ③指定したエンペローブIDにより、エンベロープの署名情報を取得する。
A20: No | C20: 論理名 | K20: 物理名 | S20: 型 | X20: 説明 | AT20: ④受信者の署名情報をループする、指定しているメールと一致している署名者があるかをチェックする。
A21: 1 | AT21: ⑤署名情報をループする、指定しているメールと一致している署名者がない場合、エラーをもどる。
A22: 2 | AT22: ⑥署名情報をループする、指定しているメールと一致している署名者が検出した場合、新メールに書き換える。
A23: 3 | AT23: ⑦署名情報をループする、指定しているメールと一致している署名者が検出した場合、新ユーザ名も反映する。
A24: 4 | AQ24: 【注意事項】
A25: 5
A26: ＣＲＵＤ | AS26: 呼び出し例
A27: No | C27: 種別 | G27: C | H27: R | I27: U | J27: D | K27: 名称 | AD27: ID | AF27: 備考 | AR27: signService.replaceEnvelopeRecipient(envelopeId,email,newName,newEmail);
A28: 1 | C28: テーブル | H28: ● | K28: 署名定義テーブル | AF28: テーブル作成中
A29: 2 | C29: テーブル | G29: ● | K29: エンベロープ情報テーブル | AF29: テーブル作成中 | AS29: ※変更したエンベロープ情報をエンベロープ情報テーブルに更新するが必要です。
A30: 3
A31: 4
A32: 5
A33: 6
A34: 7
A35: 8
A36: 9

Sheet 外部接続に関する情報
A1: 処理設計 | G1: サブシステム名 | M1: アプリ共通 | AH1: 処理名 | AN1: 外部接続に関する情報 | BZ1: 作成日 | CE1: =変更履歴!E2 -> 2021/2/18 | CK1: 更新日 | CP1: 2021/3/20
G2: サブシステムID | M2: - | BZ2: 作成者 | CE2: =変更履歴!D2 -> LKG | CK2: 更新者
A4: パッケージ名 | BU4: 処理概要
A5: クラス名
A6: 定数 | BV6: 【使用目的】
A7: No | C7: 環境 | G7: 接続先情報（接続先、プロトコル） | O7: 接続元情報（接続元、プロトコル） | AA7: メソッド | AI7: パス | AO7: 頻度 | AS7: Input | BF7: Output | BX7: Dousign、該当sheetを参照して、外部接続できるようにサーバを設定する。
A8: 1 | C8: 開発環境 | G8: https://account-d.docusign.com | O8: getAuthentication | AA8: requestJWTUserToken | AI8: /oauth/token | AO8: 1 | AS8: rsaPrivateKey | BF8: OAuthToken
AS9: clientId | BG9: accessToken | BV9: 【エラー条件】
AS10: userId | BG10: expiresIn | BX10: 特になし
AS11: expiresIn | BG11: tokenType
AS12: scopes | BG12: expiresIn
A13: 2 | C13: 開発環境 | G13: https://account-d.docusign.com | O13: getAuthentication | AA13: getUserInfo | AI13: /oauth/userinfo | AO13: 1 | AS13: accessToken | BF13: UserInfo | BV13: 【処理仕様】
BG14: Accounts | BW14: ・環境（本番、開発、ステージング、デモ・・・）
BH15: accountId | BY15: 開発API
BH16: baseUri | BZ16: https://demo.docusign.net/restapi
A17: 3 | C17: 開発環境 | G17: https://demo.docusign.net | O17: uploadSignatureFile | AA17: createEnvelope | AI17: /restapi | AO17: 1 | AS17: accountId | BF17: EnvelopeSummary | BY17: 本番API
AS18: EnvelopeDefinition | BG18: envelopeId | BZ18: https://www.docusign.net/restapi
AT19: emailSubject | BG19: status | BY19: 開発アカウント
AT20: emailBlurb | BG20: statusDateTime | BZ20: https://account-d.docusign.com
AT21: Documents[ ] | BG21: errorDetails | BY21: 本番アカウント
AU22: documentBase64 | BG22: uri | BZ22: https://account.docusign.com
AU23: name
AU24: documentId | BW24: ・接続先情報（接続先、プロトコル）
AS25: Recipients | BW25: ・接続元情報（接続先、プロトコル）
AT26: Signers[ ] | BW26: ・メソッド
AU27: Signer | BW27: ・パス
AV28: email | BW28: ・頻度
AV29: name | BW29: ・Input
AV30: recipientId | BW30: ・Output
AV31: clientUserId | BX31: サーバ起動するとき、自動的に読み込み
AV32: Tabs | BX32: ※書き換えることができます。
AW33: SignHereTabs
AX34: SignHere | BV34: 【注意事項】
AY35: documentId | BX35: ※接続元情報（接続元、プロトコル）
AY36: pageNumber | BY36: 開発API
AY37: recipientId | BZ37: https://demo.docusign.net/restapi
AY38: xPosition | BY38: 本番API
AY39: yPosition | BZ39: https://www.docusign.net/restapi
AY40: scaleValue | BY40: 開発アカウント
A41: 4 | C41: 開発環境 | G41: https://demo.docusign.net | O41: embeddedSigningByEnvelopeId | AA41: createRecipientView | AI41: /restapi | AO41: 1 | AS41: accountId | BF41: ViewUrl | BZ41: https://account-d.docusign.com
...

Sheet Sheet4
A1: メールテンプレート定義テーブル
B2: メールID | C2: MAIL_ID
B3: メールタイトル | C3: MAIL_TITLE
B4: メールテンプレート | C4: MAIL_TMP_CONTENT
B5: URLタイムアウト時間 | C5: URL_TIMEOUT
B6: 作成者ECPNO | C6: SAK_ECP_NO
B7: 作成日時 | C7: SAK_TS
B8: 更新者ECPNO | C8: KSN_ECP_NO
B9: 更新日時 | C9: KSN_TS
H13: ML_RBN | I13: メール連番
A14: メール送信履歴(ECP) | D14: メール送信履歴(CMS) | H14: ECP_NO | I14: ECPNO
B15: ML_RBN | C15: メール連番 | D15: ML_RBN | E15: メール連番 | H15: KOJ_NO | I15: 個人番号
B16: ECP_NO | C16: ECPNO | D16: KOJ_NO | E16: 個人番号 | H16: KIN_ID | I16: 機能ID
B17: KIN_ID | C17: 機能ID | D17: KIN_ID | E17: 機能ID | H17: TRK_TS | I17: 登録日時
B18: TRK_TS | C18: 登録日時 | D18: TRK_TS | E18: 登録日時 | H18: TRK_ID | I18: 登録者
B19: TRK_ID | C19: 登録者 | D19: TRK_ID | E19: 登録者 | H19: KSN_TS | I19: 更新日時
B20: KSN_TS | C20: 更新日時 | D20: KSN_TS | E20: 更新日時 | H20: KSN_ID | I20: 更新者
B21: KSN_ID | C21: 更新者 | D21: KSN_ID | E21: 更新者 | H21: VER_NO | I21: バージョンNo
B22: VER_NO | C22: バージョンNo | D22: VER_NO | E22: バージョンNo
A28: メール通知
B29: 通知ID
B30: 通知内容区分
B31: 通知方法
B32: 荷物ID
B33: 件名
B34: 送信元メールアドレス
B35: 宛先メールアドレス
B36: 返信先メールアドレス
B37: 本文
B38: 送信失敗回数
B39: 送信ステータス
B40: 送信日時
A44: エンベロープ署名依頼メール送付情報テーブル
B45: ENVELOP_ID | C45: 封筒ID
B46: TUC_ID | C46: 通知ID
B47: CLIENT_USER_ID | C47: ユーザID
B48: SAK_ECP_NO | C48: 作成者ECPNO
B49: SAK_TS | C49: 作成日時
B50: KSN_ECP_NO | C50: 更新者ECPNO
B51: KSN_TS | C51: 更新日時

Sheet TOKEN取得用
A1: 処理設計 | G1: サブシステム名 | M1: アプリ共通 | V1: 処理名 | AB1: TOKEN取得用 | BH1: 作成日 | BM1: =[1]変更履歴!E2 -> 2021/2/18 | BS1: 更新日
G2: サブシステムID | M2: - | BH2: 作成者 | BM2: =[1]変更履歴!D2 -> LKG | BS2: 更新者
A4: パッケージ名 | G4: jp.co.kuronekoyamato.commonapi.web.service | AP4: 処理概要
A5: クラス名 | G5: AzureService | V5: メソッド名 | AB5: getToken
A6: 引数 | AQ6: 【使用目的】
A7: No | C7: 入／入出 | G7: 論理名 | O7: 物理名 | W7: 型 | AC7: 説明 | AS7: Azure GraphAPIを利用して、AzureのTOKENを取得する。
A8: 1 | C8: 入力 | G8: クライアントキー | O8: client_secre | W8: String | AC8: TOKEN取得用情報
A9: 2 | C9: 入力 | G9: クライアントID | O9: client_id | W9: String | AC9: TOKEN取得用情報 | AQ9: 【エラー条件】
A10: 3 | C10: 入力 | G10: テナント | O10: tenant | W10: String | AC10: TOKEN取得用情報 | AS10: 特になし
AQ14: 【処理仕様】
AT15: ①TOKEN取得用情報（client_secre、client_id、tenant）をプロパティファイルから取得する。
AT16: ②TOKEN取得用URLを作成する。
AT17: ③TOKEN取得用URLでGraphAPIを呼ばだす。
A18: 戻り値 | AT18: ④GraphAPIのレスポンスからTOKENを取得して戻り値に設定する。
A19: No | C19: 論理名 | K19: 物理名 | S19: 型 | X19: 説明
A20: 1 | C20: トークン | K20: Token | S20: String | X20: ログイン後のToken
A21: 2
A22: 3
A23: 4
A24: 5 | AQ24: 【注意事項】
A25: ＣＲＵＤ | AS25: 呼び出し例
A26: No | C26: 種別 | G26: C | H26: R | I26: U | J26: D | K26: 名称 | AD26: ID | AF26: 備考 | AT26: String token =
A27: 1 | AT27: AzureService.getToken();
A28: 2
A29: 3
A30: 4
A31: 5
A32: 6
A33: 7
A34: 8
A35: 9

Sheet ADユーザ無効化
A1: 処理設計 | G1: サブシステム名 | M1: アプリ共通 | V1: 処理名 | AB1: アカウント無効化 | BH1: 作成日 | BM1: =[1]変更履歴!E2 -> 2021/2/18 | BS1: 更新日
G2: サブシステムID | M2: - | BH2: 作成者 | BM2: =[1]変更履歴!D2 -> LKG | BS2: 更新者
A4: パッケージ名 | G4: jp.co.kuronekoyamato.commonapi.web.service | AP4: 処理概要
A5: クラス名 | G5: AzureService | V5: メソッド名 | AB5: disableAdUser
A6: 引数 | AQ6: 【使用目的】
A7: No | C7: 入／入出 | G7: 論理名 | O7: 物理名 | W7: 型 | AC7: 説明 | AS7: スタッフECPNOに紐付けている、アカウントについて、Azure GraphAPIを利用して、アカウントを無効化にする。
A8: 1 | C8: 入力 | G8: ユーザID | O8: oID | W8: String | AC8: Azure AD B2CのログインユーザID
A9: 2 | C9: 入力 | G9: 認証情報 | O9: authorization | W9: String | AC9: AzureのTOKEN | AQ9: 【エラー条件】
AS10: 特になし
AQ14: 【処理仕様】
AT15: ①oID、authorizationでアカウント無効化URLを作成する。
AT16: ②アカウント無効化URLでGraphAPIを呼ばだす。
A18: 戻り値
A19: No | C19: 論理名 | K19: 物理名 | S19: 型 | X19: 説明 | AQ19: 【注意事項】
A20: 1 | AS20: 呼び出し例
A21: 2
A22: 3 | AT22: AzureService.disableAdUser(oID, authorization);
A23: 4
A24: 5
A25: ＣＲＵＤ
A26: No | C26: 種別 | G26: C | H26: R | I26: U | J26: D | K26: 名称 | AD26: ID | AF26: 備考
A27: 1
A28: 2
A29: 3
A30: 4
A31: 5
A32: 6
A33: 7
A34: 8
A35: 9

Sheet ADパスワード初期化
A1: 処理設計 | G1: サブシステム名 | M1: アプリ共通 | V1: 処理名 | AB1: ADパスワード初期化 | BH1: 作成日 | BM1: =[1]変更履歴!E2 -> 2021/2/18 | BS1: 更新日
G2: サブシステムID | M2: - | BH2: 作成者 | BM2: =[1]変更履歴!D2 -> LKG | BS2: 更新者
A4: パッケージ名 | G4: jp.co.kuronekoyamato.commonapi.web.service | AP4: 処理概要
A5: クラス名 | G5: AzureService | V5: メソッド名 | AB5: InitAdUserPassword
A6: 引数 | AQ6: 【使用目的】
A7: No | C7: 入／入出 | G7: 論理名 | O7: 物理名 | W7: 型 | AC7: 説明 | AS7: スタッフECPNOに紐付けている、アカウントについて、Azure GraphAPIを利用して、パスワードを初期化にする。
A8: 1 | C8: 入力 | G8: ユーザID | O8: oID | W8: String | AC8: Azure AD B2CのログインユーザID
A9: 2 | C9: 入力 | G9: 認証情報 | O9: authorization | W9: String | AC9: AzureのTOKEN | AQ9: 【エラー条件】
AS10: 特になし
AQ14: 【処理仕様】
AT15: ①oID、authorizationでパスワード初期化URLを作成する。
AT16: ②パスワード初期化URLでGraphAPIを呼ばだす。
A18: 戻り値
A19: No | C19: 論理名 | K19: 物理名 | S19: 型 | X19: 説明 | AQ19: 【注意事項】
A20: 1 | AS20: 呼び出し例
A21: 2
A22: 3 | AT22: AzureService.InitAdUserPassword(oID, authorization);
A23: 4
A24: 5
A25: ＣＲＵＤ
A26: No | C26: 種別 | G26: C | H26: R | I26: U | J26: D | K26: 名称 | AD26: ID | AF26: 備考
A27: 1
A28: 2
A29: 3
A30: 4
A31: 5
A32: 6
A33: 7
A34: 8
A35: 9
